Workbook

Sheet TestProgress
A1: All
A2: Status | B2: Test Progress | C2: Test Progress (%)
A3: Not Start | B3: =COUNTIF(Creator_Dee!$L:$L,A3) -> 108 | C3: =IF(B3=0,0,B3/($B$10)) -> 0.94736842
A4: PASS | B4: =COUNTIF(Creator_Dee!$L:$L,A4) -> 6 | C4: =IF(B4=0,0,B4/($B$11-$B$9-$B$8)) -> 1
A5: FAIL | B5: =COUNTIF(Creator_Dee!$L:$L,A5) -> 0 | C5: =IF(B5=0,0,B5/($B$11-$B$9)) -> 0
A6: BLOCKED | B6: =COUNTIF(Creator_Dee!$L:$L,A6) -> 0 | C6: =IF(B6=0,0,B6/($B$11-$B$9)) -> 0
A7: In Progress | B7: =COUNTIF(Creator_Dee!$L:$L,A7) -> 0 | C7: =IF(B7=0,0,B7/($B$11-$B$9)) -> 0
A8: Deferred | B8: =COUNTIF(Creator_Dee!$L:$L,A8) -> 0 | C8: =IF(B8=0,0,B8/($B$11)) -> 0
A9: N/A | B9: =COUNTIF(Creator_Dee!$L:$L,A9) -> 0 | C9: =IF(B9=0,0,B9/($B$11)) -> 0
A10: Total | B10: =SUM(B3:B9) -> 114
A11: Execution Progress | B11: =SUM(B4:B9) -> 6 | C11: =IF($B$11=0,0,$B$11/$B$10) -> 0.052631579
A14: Not Start + Execution Progress = 100
A15: Pass to Deferred = 100
A16: ทุกอย่าง/Execution Progress ยกเว้น Not Start/Total
A17: N/A ไม่เอามานับรวม
A21: All
A22: Status | B22: Test Progress | C22: Test Progress (%)
A23: Not Start | B23: =COUNTIF(Income_Summary!$L:$L,A23) -> 8 | C23: =IF(B23=0,0,B23/($B$30)) -> 0.57142857
A24: PASS | B24: =COUNTIF(Creator_Dee!$L:$L,A24) -> 6 | C24: =IF(B24=0,0,B24/($B$31-$B$29-$B$28)) -> 1
A25: FAIL | B25: =COUNTIF(Creator_Dee!$L:$L,A25) -> 0 | C25: =IF(B25=0,0,B25/($B$31-$B$29)) -> 0
A26: BLOCKED | B26: =COUNTIF(Creator_Dee!$L:$L,A26) -> 0 | C26: =IF(B26=0,0,B26/($B$31-$B$29)) -> 0
A27: In Progress | B27: =COUNTIF(Creator_Dee!$L:$L,A27) -> 0 | C27: =IF(B27=0,0,B27/($B$31-$B$29)) -> 0
A28: Deferred | B28: =COUNTIF(Creator_Dee!$L:$L,A28) -> 0 | C28: =IF(B28=0,0,B28/($B$31)) -> 0
A29: N/A | B29: =COUNTIF(Creator_Dee!$L:$L,A29) -> 0 | C29: =IF(B29=0,0,B29/($B$31)) -> 0
A30: Total | B30: =SUM(B23:B29) -> 14
A31: Execution Progress | B31: =SUM(B24:B29) -> 6 | C31: =IF($B$11=0,0,$B$31/$B$30) -> 0.42857143

Sheet Summary
A1: No | B1: Module Name | C1: Planned Execution | E1: Actual Execution | G1: TCs Generated | H1: TCs Executed | I1: TCs Pending | J1: TCs Deferred | K1: TCs Not Applicable | L1: TCs Pass | M1: TCs Fail | N1: Achieved % | O1: Pass % | P1: TCs Left | Q1: Module Progress | R1: Upload Test Result ลง GG Drive | S1: Create TC by | T1: Execute by | U1: Remark
C2: Start | D2: End | E2: Start | F2: End
A3: 1 | B3: Dashboard + Deal | G3: =Creator_Dee!F220 -> 100 | H3: =L3+M3 -> 6 | I3: =Creator_Dee!F217 -> 0 | J3: =Creator_Dee!F218 -> 0 | K3: =Creator_Dee!F219 -> 0 | L3: =Creator_Dee!F214 -> 6 | M3: =Creator_Dee!F215 -> 0 | N3: =(H3+I3+K3)/G3 -> 0.06 | O3: =L3/(G3-J3-K3) -> 0.06 | P3: =G3-H3-I3-J3-K3 -> 94 | Q3: Not Start | R3: Not Start
A4: 2 | B4: Calendar | G4: =Calendar!F120 -> 77 | H4: =L4+M4 -> 19 | I4: =Calendar!F117 -> 0 | J4: =Calendar!F118 -> 0 | K4: =Calendar!F119 -> 0 | L4: =Calendar!F114 -> 19 | M4: =Calendar!F115 -> 0 | N4: =(H4+I4+K4)/G4 -> 0.24675325 | O4: =L4/(G4-J4-K4) -> 0.24675325 | P4: =G4-H4-I4-J4-K4 -> 58 | Q4: Not Start | R4: Not Start
A5: 3 | B5: User Package | G5: =User_Package!F118 -> 71 | H5: =L5+M5 -> 55 | I5: =User_Package!F115 -> 0 | J5: =User_Package!F116 -> 2 | K5: =User_Package!F117 -> 0 | L5: =User_Package!F112 -> 51 | M5: =User_Package!F113 -> 4 | N5: =(H5+I5+K5)/G5 -> 0.77464789 | O5: =L5/(G5-J5-K5) -> 0.73913043 | P5: =G5-H5-I5-J5-K5 -> 14 | Q5: Not Start | R5: Not Start
A6: 4 | B6: Business_Profile | G6: =Business_Profile!F46 -> 13 | H6: =L6+M6 -> 0 | I6: =Business_Profile!F47 -> 0 | J6: =Business_Profile!F48 -> 0 | K6: =Business_Profile!F49 -> 0 | L6: =Business_Profile!F44 -> 0 | M6: =Business_Profile!F45 -> 0 | N6: =(H6+I6+K6)/G6 -> 0 | O6: =L6/(G6-J6-K6) -> 0 | P6: =G6-H6-I6-J6-K6 -> 13 | Q6: Not Start | R6: Not Start
A7: 5 | B7: Create_content | G7: =Create_content!F86 -> 47 | H7: =L7+M7 -> 0 | I7: =Create_content!F87 -> 0 | J7: =Create_content!F88 -> 0 | K7: =Create_content!F89 -> 0 | L7: =Create_content!F84 -> 0 | M7: =Create_content!F85 -> 0 | N7: =(H7+I7+K7)/G7 -> 0 | O7: =L7/(G7-J7-K7) -> 0 | P7: =G7-H7-I7-J7-K7 -> 47 | Q7: Not Start | R7: Not Start
A8: Total Progress | G8: =SUM(G3:G5) -> 248 | H8: =M8+L8 -> 80 | I8: =SUM(I3:I5) -> 0 | J8: =SUM(J3:J5) -> 2 | K8: =SUM(K3:K5) -> 0 | L8: =SUM(L3:L5) -> 76 | M8: =SUM(M3:M5) -> 4 | N8: =(H8+I8+J8+K8)/G8 -> 0.33064516 | O8: =L8/(G8-J8-K8) -> 0.30894309 | P8: =SUM(P3:P5) -> 166
A11: Figma
A13: Design Case
A16: CW
A17: FSD
A18: Defect
A19: Test Result

Sheet Creator_Dee
B1: =HYPERLINK("#Document!A1", "Refer to sheet Document") -> Refer to sheet Document
A3: Total TC. | B3: =COUNTIF(A13:A182,"TC_*") -> 114
A4: Test Cases ID | B4: Test Case Description | C4: Pre-Conditions | D4: Test Step | E4: Expected Result | F4: Positive/Negative | G4: Priority | H4: Test Data | I4: Tester | J4: Execution Plan | K4: Execution date | L4: Test Result | M4: Remark
A10: CreatorDee
A11: Scenario : Case validations : เมนู "หลัก"
A12: ="TC_Creator_Dee_"&(ROW()-ROW($A$12)+1) -> TC_Creator_Dee_1 | B12: ตรวจสอบเมนู : หน้าหลัก กรณี : บัญชีที่ยังไม่มีข้อมูลดีลเลย ระบบแสดงตัวเลข 0 ในทุกกล่อง summary ระบบแสเดงหน้าจอถูกต้อง เงื่อนไข -กดเมนู : หน้าหลัก (บัญชีใหม่ ไม่มีดีล) | E12: -ระบบแสดงหน้า หลัก โดยยังไม่มีรายการ ดีล - ระบบแสดงตัวเลข 0 ในกล่อง summar รายได้เดือนนี้ / เงินค้าง / ดีลที่กำลังทำอยู่ | F12: Positive | G12: Medium | I12: Garfield | L12: PASS
A13: ="TC_Creator_Dee_"&(ROW()-ROW($A$12)+1) -> TC_Creator_Dee_2 | B13: ตรวจสอบเมนู : หน้าหลัก กรณี : กด กล่อง summary "รายได้เดือนนี้" ระบบแสดงหน้าจอถูกต้อง (ยอดรวมดีลที่กดรับเงินแล้วในเดือนปัจจุบัน) เงื่อนไข -กดเมนู : หน้าหลัก -กด : "รายได้เดือนนี้" | E13: - ระบบแสดงพาไปหน้า สรุปการเงิน แสดงรายละเอียดถูกต้อง - ระบบแสดงกล่อง ยอดเงินเข้าจริง (หลังหัก ณ ที่จ่าย)/ ยอดเงินค้างรับรวม /หัก ณ ที่จ่ายสะสม - ระบบแสดง เครื่องมือภาษี ใบ 50 ทวิ/ รายจ่าย / เตรียมยื่นภาษี | F13: Positive | G13: Medium | I13: Garfield | L13: PASS
A14: ="TC_Creator_Dee_"&(ROW()-ROW($A$12)+1) -> TC_Creator_Dee_3 | B14: ตรวจสอบเมนู : หน้าหลัก กรณี : กดกล่อง summary "เงินค้างรับ" ระบบแสดงหน้าจอถูกต้อง (ยอดรวมดีลสถานะรอรับเงินทั้งหมด) เงื่อนไข -กดเมนู : หน้าหลัก -กด : "เงินค้างรับ" | C14: Pre-Conditions | E14: - ระบบแสดงพาไปหน้า ดีล แสดงรายละเอียดถูกต้อง - ระบบแสดงรายการ ดีล สถานะ "รอจ่าย" ของแต่ละเดือน | F14: Positive | G14: Medium | I14: Garfield | L14: PASS
A15: ="TC_Creator_Dee_"&(ROW()-ROW($A$12)+1) -> TC_Creator_Dee_4 | B15: ตรวจสอบเมนู : หน้าหลัก กรณี : กดกล่อง summary "ดีลที่กำลังทำ" ระบบแสดงจำนวนดีลในสถานะกำลังทำงานถูกต้อง เงื่อนไข -กดเมนู : หน้าหลัก -กด : "ดีลที่กำลังทำ" | C15: Pre-Conditions | E15: - ระบบแสดงพาไปหน้า ดีลทั้งหมดที่แสดงรายละเอียดถูกต้อง | F15: Positive | G15: Medium | I15: Garfield | L15: PASS
A16: ="TC_Creator_Dee_"&(ROW()-ROW($A$12)+1) -> TC_Creator_Dee_5 | B16: ตรวจสอบเมนู : หน้าหลัก สิ่งที่ควรจัดการ กรณี มีรายการ ดีล > 3 รายการ โดยมีมรายละเอียดดังนี้ ระบบแสดงหน้าจอถูกต้อง เงื่อนไข -กดเมนู : หน้าหลัก -มีรายการ ดีล : ใกล้ / เลยนัดส่งสคริป์ต 1 รายการ -มีรายการ ดีล : ใกล้ / เลย นัดส่ง draft > 1 รายการ -มีรายการ ดีล : อยู่ในช่วง เตือน Exclusivity 2 รายการ -มีรายการ ดีล : จ่ายเงินแล้ว แต่ยังไม่ออกเอกสาร | E16: - ระบบแสดงรายการ ดีล แต่ละหัวข้อได้ถูกต้อง | F16: Positive | G16: Medium | I16: Garfield | L16: PASS
A17: ="TC_Creator_Dee_"&(ROW()-ROW($A$12)+1) -> TC_Creator_Dee_6 | B17: ตรวจสอบเมนู : หน้าหลัก มีรายการ "สิ่งที่ควรจัดการ" สถานะ "ด่วนมาก" กรณี กดที่ ปุ่ม : "ดูดีล" ระบบแสดงหน้าจอถูกต้อง เงื่อนไข -กดเมนู : หน้าหลัก -กดปุ่ม : ดูดีล | C17: Pre-Conditions | E17: -ระบบพาไปหน้าเมนู : ดีล แสดงรายละเอียด ดีล ทั้งหมดถูกต้อง | F17: Positive | G17: Medium | I17: Garfield | L17: PASS
A18: ="TC_Creator_Dee_"&(ROW()-ROW($A$12)+1) -> TC_Creator_Dee_7 | B18: ตรวจสอบเมนู : หน้าหลัก มีรายการ "สิ่งที่ควรจัดการ" สถานะ "ด่วนมาก" กรณี กดที่ ปุ่ม : "เลื่อนเตือน อีก 3 วัน " ระบบแสดงหน้าจอถูกต้อง เงื่อนไข -กดเมนู : หน้าหลัก -กดปุ่ม :เลื่อนเตือน -popup : เลือก อีก 3 วัน -กดปุ่ม : เลื่อน | C18: Pre-Conditions | E18: -ระบบแสดง popup : เลื่อนเตือน "ซ่อนรายการนี้ไว้ก่อน แล้วเตือนอีกครั้งใน" -แสดงปุ่ม : ยกเลิก , เลื่อน - รายการ ดีล "ดีลด่วน" หายไปจากหน้า หลัก | F18: Positive | G18: Medium | H18: กางเคสระยะเวลาที่จะตกแต่ละสถานะ | L18: Not Start
A19: ="TC_Creator_Dee_"&(ROW()-ROW($A$12)+1) -> TC_Creator_Dee_8 | B19: ตรวจสอบเมนู : หน้าหลัก มีรายการ "สิ่งที่ควรจัดการ" กรณี กดที่ ปุ่ม : "รับทราบ" ระบบแสดงหน้าจอถูกต้อง เงื่อนไข -กดเมนู : หน้าหลัก | C19: Pre-Conditions | E19: -ระบบแสดง รายการ ดีล "ดีลด่วน" ที่เลื่อนเตือนไปแสดงรายการดีลถูกต้อง | F19: Positive | G19: Medium | L19: Not Start
A20: Scenario : Case validations : เมนู "ดีล"
A21: บันทึกดีลเข้าระบบ
A22: ="TC_Creator_Dee_"&(ROW()-ROW($A$12)+1-2) -> TC_Creator_Dee_9 | B22: ตรวจสอบเมนู : ดีล กรณี "ยังไม่มีรายการดีล" ระบบและแสดงรายการทั้งหมดถูกต้อง เงื่อนไข - กดเมนู : ดีล | E22: -ระบบแสดงหน้า ดีล ถูกต้อง โดยแสดงช่อง คเนหาชื่อประเภทแบรน์ด / drop down ปี / drop down หมวดหมู่สิ้นค้า / drop down สถานะ - แสดงปุ่ม "ล้าง" -แสดงปุ่ม "Export" -แสดงปุ่ม "เพิ่มดิล" | F22: Positive | G22: High | L22: Not Start
A23: ="TC_Creator_Dee_"&(ROW()-ROW($A$12)+1-2) -> TC_Creator_Dee_10 | B23: ตรวจสอบเมนู : ดีล กดปุ่ม "เพิ่มดีล" User สร้างดีล กรอกข้อมูลครบทุก Field กรณี : "วันที่นัดส่งสคริปต์ให้แบรนด์รีวิว / วันนัดส่ง draft/งาน > (Current date = 3 วัน) ไม่กด "ช่วยคิดเรต" ระบบสร้างดีลสำเร็จ และแสดงรายการทั้งหมดถูกต้อง เงื่อนไข - กดเมนู : ดีล - กดปุ่ม : เพิ่มดีล - All Field : กรอกข้อมูลครบทุก - Field : วันที่นัดส่งสคริปต์ให้แบรนด์รีวิว / วันนัดส่ง draft/งาน > (Current date = 3 วัน) - กด : "เพิ่มดีล" | E23: หน้าหลัก -ระบบแสดงรายการ ดีล ใกล้นัดส่ง สคริปต์ · test สถานะ : ด่วน -ระบบแสดงรายการดีล ใกล้นัดส่ง draft/งาน · test สถานะ : ด่วน หน้าดีล -ระบบแสดงรายละเอียดที่หน้า ดีล ถูกต้อง โดยแสดง หมายเหตุ : ใกล้ deadline | F23: Positive | G23: High | L23: Not Start
A24: ="TC_Creator_Dee_"&(ROW()-ROW($A$12)+1-2) -> TC_Creator_Dee_11 | B24: ตรวจสอบเมนู : ดีล กดปุ่ม "เพิ่มดีล" กรณี User สร้างดีล โดย "ไม่กรอกชื่อแบรนด์ / ไม่กรอกประเภทงาน" และกดปุ่ม "เพิ่มดีล" ระบบ error ถูกต้อง เงื่อนไข - กดเมนู : ดีล - กดปุ่ม : เพิ่มดีล - Field ชื่อแบรนด์ / ประเภทงาน : ไม่กรอกข้อมูล - Other field : กรอกข้อมูลครบ - กด "เพิ่มดีล" | C24: Pre-Conditions | E24: หน้าดีล -ระบบแสดง error : " ใส่ชื่อแบรนด์" ใต้ Field ถูกต้อง -ระบบแสดง error : " ใส่ประเภทงาน" ใต้ Field ถูกต้อง -ไม่สามารถสร้างดีลได้ | F24: Negative | G24: High | L24: Not Start
A25: ="TC_Creator_Dee_"&(ROW()-ROW($A$12)+1-2) -> TC_Creator_Dee_12 | B25: ตรวจสอบเมนู : ดีล กดปุ่ม "เพิ่มดีล" กรณี User สร้างดีลชื่อแบรนด์ซ้ำ "เพิ่มดีล" สามารถทำการสร้างดีลได้สำเร็จ เงื่อนไข - กดเมนู : ดีล - กดปุ่ม : เพิ่มดีล - Field ชื่อแบรนด์ : กรอกชื่อแบรนด์ซ้ำ - กด "เพิ่มดีล" | E25: หน้าดีล -ระบบแสดงรายละเอียดที่หน้า ดีล ถูกต้อง โดยแสดงชื่อแบรนด์ถูกต้อง | F25: Positive | G25: Medium | H25: -ระบบสร้างชื่อแบร์นดซ้ำได้ | L25: Not Start
A26: ="TC_Creator_Dee_"&(ROW()-ROW($A$12)+1-2) -> TC_Creator_Dee_13 | B26: ตรวจสอบเมนู : ดีล กดปุ่ม "เพิ่มดีล" กรณีกรอกข้อมูล Field : ชื่อแบรนด์ * / ประเภทงาน * / ช่องทางที่ติดต่อ / ราคา (บาท) ครบถ้วน และกด เมนู "ช่วยคิดเรต" ระบบหน้าจอถูกต้อง เงื่อนไข - กดเมนู : ดีล - กดปุ่ม : เพิ่มดีล - All field : กรอกข้อมูลครบทุก - กด : "ช่วยคิดเรต" | E26: -ระบบพาไปหน้า "ประเมินราคางานที่ควรเสนอ" ถูกต้อง | F26: Positive | G26: Medium | L26: Not Start
A27: ="TC_Creator_Dee_"&(ROW()-ROW($A$12)+1-2) -> TC_Creator_Dee_14 | B27: ตรวจสอบเมนู : ดีล กดปุ่ม "เพิ่มดีล" กรณี User ไม่กรอกข้อมูล Field ทั้งหมด และกดปุ่ม "ช่วยคิดเรต" ระบบหน้าจอถูกต้อง เงื่อนไข - All field : ไม่กรอกข้อมูล - กด : "ช่วยคิดเรต" | E27: หน้าดีล -ระบบแสดง error : "กรอกจำนวนผู้ติดตาม หรือยอดวิวเฉลี่ยอย่างน้อยหนึ่งค่า" ถูกต้อง | F27: Negative | G27: High | L27: Not Start
A28: ="TC_Creator_Dee_"&(ROW()-ROW($A$12)+1-2) -> TC_Creator_Dee_15 | B28: ตรวจสอบเมนู : ดีล กดปุ่ม "เพิ่มดีล" กรณี : User มีการสร้างดีลโดยมีเพียง วันที่นัดส่งสคริปต์ให้แบรนด์รีวิว และยังห่างจากวันปัจจุบันเกิน 3 วัน เงื่อนไข - วันที่นัดส่งสคริปต์ให้แบรนด์รีวิว > (Current date + 3 วัน) | E28: หน้าหลัก -ระบบแสดงรายการ ดีล ใกล้นัดส่ง สคริปต์ สถานะ : ด่วน หน้าดีล -ระบบแสดงรายละเอียดที่หน้า ดีล ถูกต้อง โดยแสดง หมายเหตุ : ใกล้ deadline | F28: Positive | G28: Medium | L28: Not Start | M28: TC_Calendar_2
A29: ="TC_Creator_Dee_"&(ROW()-ROW($A$12)+1-2) -> TC_Creator_Dee_16 | B29: ตรวจสอบเมนู : ดีล กดปุ่ม "เพิ่มดีล" กรณี : สร้างดีลโดยมีเพียง วันที่นัดส่งสคริปต์ให้แบรนด์รีวิว และเกือบจะถึง deadline แล้ว (= 3 วัน) เงื่อนไข - วันที่นัดส่งสคริปต์ให้แบรนด์รีวิว = (Current date ) แต่ไม่ต่ำกว่า Current Date | E29: หน้าหลัก -ระบบแสดงรายการ ดีล ใกล้นัดส่ง สคริปต์ สถานะ : ด่วน หน้าดีล -ระบบแสดงรายละเอียดที่หน้า ดีล ถูกต้อง โดยแสดง หมายเหตุ : ใกล้ deadline | F29: Positive | G29: Medium | L29: Not Start | M29: TC_Calendar_3
A30: ="TC_Creator_Dee_"&(ROW()-ROW($A$12)+1-2) -> TC_Creator_Dee_17 | B30: ตรวจสอบเมนู : ดีล กดปุ่ม "เพิ่มดีล" กรณี : สร้างดีลโดยมีเพียง วันที่นัดส่งสคริปต์ให้แบรนด์รีวิว แต่เลย deadline แล้ว (< Current date) เงื่อนไข - สถานะดีล : ทาบทาม - วันที่นัดส่งสคริปต์ให้แบรนด์รีวิว < (Current date) | E30: หน้าหลัก -ระบบแสดงรายการ ดีล เลยนัดส่ง สคริปต์ สถานะ : ด่วนมาก หน้าดีล -ระบบแสดงรายละเอียดที่หน้า ดีล ถูกต้อง โดยแสดง หมายเหตุ : เลย deadline | F30: Positive | G30: Medium | L30: Not Start | M30: TC_Calendar_4
A31: ="TC_Creator_Dee_"&(ROW()-ROW($A$12)+1-2) -> TC_Creator_Dee_18 | B31: ตรวจสอบเมนู : ดีล กดปุ่ม "เพิ่มดีล" กรณี : สร้างดีลโดยมีเพียง วันที่นัดส่ง draft / งาน และยังห่างจากวันปัจจุบันเกิน 3 วัน เงื่อนไข - สถานะดีล : ทาบทาม - วันที่นัดส่ง draft / งาน > (Current date + 3 วัน) | E31: หน้าหลัก -ระบบแสดงรายการ ดีล ใกล้นัดส่ง draft/งาน สถานะ : ด่วน หน้าดีล -ระบบแสดงรายละเอียดที่หน้า ดีล ถูกต้อง โดยแสดง หมายเหตุ : ใกล้ deadline | F31: Positive | G31: Medium | L31: Not Start | M31: TC_Calendar_5
A32: ="TC_Creator_Dee_"&(ROW()-ROW($A$12)+1-2) -> TC_Creator_Dee_19 | B32: ตรวจสอบเมนู : ดีล กดปุ่ม "เพิ่มดีล" กรณี : สร้างดีลโดยมีเพียง วันที่นัดส่ง draft / งาน และเกือบจะถึง deadline แล้ว (<= 3 วัน) เงื่อนไข - สถานะดีล : ทาบทาม - วันที่นัดส่ง draft / งาน <= (Current date + 3 วัน) แต่ไม่ต่ำกว่า Current Date | E32: หน้าหลัก -ระบบแสดงรายการ ดีล ใกล้นัดส่ง draft/งาน สถานะ : ด่วน หน้าดีล -ระบบแสดงรายละเอียดที่หน้า ดีล ถูกต้อง โดยแสดง หมายเหตุ : ใกล้ deadline | F32: Positive | G32: Medium | L32: Not Start | M32: TC_Calendar_6
A33: ="TC_Creator_Dee_"&(ROW()-ROW($A$12)+1-2) -> TC_Creator_Dee_20 | B33: ตรวจสอบเมนู : ดีล กดปุ่ม "เพิ่มดีล" กรณี : User มีการสร้างดีลโดยมีเพียง วันที่นัดส่ง draft / งาน แต่เลย deadline แล้ว (< Current date) เงื่อนไข - สถานะดีล : ทาบทาม - วันที่นัดส่ง draft / งาน < (Current date) | E33: หน้าหลัก -ระบบแสดงรายการ ดีล เลยนัดส่ง draft/งาน สถานะ : ด่วนมาก หน้าดีล -ระบบแสดงรายละเอียดที่หน้า ดีล ถูกต้อง โดยแสดง หมายเหตุ : เลย deadline | F33: Positive | G33: Medium | L33: Not Start | M33: TC_Calendar_7
A34: ="TC_Creator_Dee_"&(ROW()-ROW($A$12)+1-2) -> TC_Creator_Dee_21 | B34: ตรวจสอบเมนู : ดีล กดปุ่ม "เพิ่มดีล" กรณี : User มีการสร้างดีลโดยมีเพียง วันลงงาน / เผยแพร่ และยังห่างจากวันปัจจุบันเกิน 3 วัน เงื่อนไข - สถานะดีล : ทาบทาม - วันลงงาน / เผยแพร่ > (Current date + 3 วัน) | E34: หน้าหลัก -ระบบแสดงรายการ ดีล อยู่ในหมวดหมู่ "ดีลที่ยังไม่ได้นัดวัน" หน้าดีล -ระบบแสดงรายละเอียดที่หน้า ดีล ถูกต้อง โดยแสดง ไม่แสดงแจ้งเตือน หมายเหตุ | F34: Positive | G34: Medium | L34: Not Start | M34: TC_Calendar_8
A35: ="TC_Creator_Dee_"&(ROW()-ROW($A$12)+1-2) -> TC_Creator_Dee_22 | B35: ตรวจสอบเมนู : ดีล กดปุ่ม "เพิ่มดีล" กรณี : User มีการสร้างดีลโดยมีเพียง วันลงงาน / เผยแพร่ และเกือบจะถึง deadline แล้ว (<= 3 วัน) เงื่อนไข - สถานะดีล : ทาบทาม - วันลงงาน / เผยแพร่ <= (Current date + 3 วัน) แต่ไม่ต่ำกว่า Current Date | E35: หน้าหลัก -ระบบแสดงรายการ ดีล อยู่ในหมวดหมู่ "ดีลที่ยังไม่ได้นัดวัน" หน้าดีล -ระบบแสดงรายละเอียดที่หน้า ดีล ถูกต้อง โดยแสดง ไม่แสดงแจ้งเตือน หมายเหตุ | F35: Positive | G35: Medium | L35: Not Start | M35: TC_Calendar_9
A36: ="TC_Creator_Dee_"&(ROW()-ROW($A$12)+1-2) -> TC_Creator_Dee_23 | B36: ตรวจสอบเมนู : ดีล กดปุ่ม "เพิ่มดีล" กรณี : User มีการสร้างดีลโดยมีเพียง วันลงงาน / เผยแพร่ แต่เลย deadline แล้ว (< Current date) เงื่อนไข - สถานะดีล : ทาบทาม - วันลงงาน / เผยแพร่ < (Current date) | E36: หน้าหลัก -ระบบแสดงรายการ ดีล อยู่ในหมวดหมู่ "ดีลที่ยังไม่ได้นัดวัน" หน้าดีล -ระบบแสดงรายละเอียดที่หน้า ดีล ถูกต้อง โดยแสดง หมายเหตุ : เลยวันลง FYI : ระบบต้องแจ้งเตือนที่หน้าหลัก สถานะ "ด่วนมาก" ? | F36: Positive | G36: Medium | L36: Not Start | M36: TC_Calendar_10
A37: ="TC_Creator_Dee_"&(ROW()-ROW($A$12)+1-2) -> TC_Creator_Dee_24 | B37: ตรวจสอบเมนู : ดีล Field "วันที่นัดส่งสคริปต์ให้แบรนด์รีวิว" กรณี User กรอกข้อมูล "ปีย้อนหลัง = 2568" และกดปุ่ม "เพิ่มดิล" ระบบแสดงหน้าจอถูกต้อง เงื่อนไข -Field วันที่นัดส่งสคริปต์ให้แบรนด์รีวิว : 1 ก.ค. ปี (2568) | E37: หน้าหลัก -ระบบแสดงรายการ ดีล อยู่ในหมวดหมู่ "ดีลที่ยังไม่ได้นัดวัน" หน้าดีล -ระบบแสดงรายการ ดีล อยู่ในหมวดหมู่ "กรกฎาคม 2568". แสดงรายละเอียดที่หน้า ดีล ถูกต้อง โดยแสดง หมายเหตุ : เลยวันลง | F37: Positive | G37: High | L37: Not Start
A38: ="TC_Creator_Dee_"&(ROW()-ROW($A$12)+1-2) -> TC_Creator_Dee_25 | B38: ตรวจสอบเมนู : ดีล กดปุ่ม "เพิ่มดีล" Field "วันที่นัดส่ง draft / งาน" กรณี User กรอกข้อมูล "เดือน = มิถุนายน" และกดปุ่ม "เพิ่มดิล" ระบบแสดงหน้าจอถูกต้อง เงื่อนไข -Field วันที่นัดส่ง draft / งาน : "เดือน = มิถุนายน" | E38: หน้าหลัก -ระบบแสดงรายการ ดีล เลยนัดส่ง draft/งาน สถานะ : ด่วนมาก หน้าดีล -ระบบสร้างดีลของเดือน "มิถุยนายน" สำเร็จ รายการแสดงที่หน้า "ดีล" -ระบบแสดงสถานะ "ทาบทาม" ถูกต้อง | F38: Positive | G38: High | L38: Not Start
A39: ="TC_Creator_Dee_"&(ROW()-ROW($A$12)+1-2) -> TC_Creator_Dee_26 | B39: ตรวจสอบเมนู : ดีล กดปุ่ม "เพิ่มดีล" กำหนดการ & การจ่ายเงิน Field "กำหนดจ่ายเงิน" กรณี กรอกข้อมูล "ปีย้อนหลัง = 2568" และกดปุ่ม "เพิ่มดิล"ระบบแสดงหน้าจอถูกต้อง เงื่อนไข -Field "กำหนดจ่ายเงิน" : " 5 ก.ค. ปี (2568) | E39: หน้าหลัก -ระบบแสดงรายการ ดีล ข้อมูลยังไม่ครบ หน้าดีล -ระบบสร้างดีล ฮยู่ในหมวด "ไม่ระบุเดือน" สำเร็จ รายการแสดงที่หน้า "ดีล" -ระบบแสดงสถานะ "ทาบทาม" ถูกต้อง | F39: Positive | G39: High | L39: Not Start
A40: ="TC_Creator_Dee_"&(ROW()-ROW($A$12)+1-2) -> TC_Creator_Dee_27 | B40: ตรวจสอบเมนู : เพิ่มดีล และ กดปุ่ม "ช่วยคิดเรต" กรณี User กรอกยอด Engagement ทั้งหมด แล้วกด "คำนวณเรต" โดยมีรายละเอียด ระบบแสดงหน้าจอถูกต้อง เงื่อนไข - กด : ช่วยคิดเรต - Field ไลก์ : 5,000 - Field คอมเมนต์ : 100 - Field เซฟ : 1,000 - Filed แชร์ : 550 - กดปุ่ม : "คำนวณเรต" | E40: -ระบบคำนวณคิดเรตงานจากยอด Engagement ได้ถูกต้อง -ระบบแสดงยอด ราคาที่แนะนำ 3 ราคามาให้เลือก : Low/Market / Premium | F40: Positive | G40: High | L40: Not Start
A41: ="TC_Creator_Dee_"&(ROW()-ROW($A$12)+1-2) -> TC_Creator_Dee_28 | B41: ตรวจสอบเมนู : ดีล กดปุ่ม "ช่วยคิดเรต" กรณี ไม่กรอกยอด Engagement ทั้งหมด แล้วกด "คำนวณเรต"ระบบแสดงหน้าจอถูกต้อง เงื่อนไข - กด : ช่วยคิดเรต - All Field : ไม่กรอกข้อมูล - กดปุ่ม : "คำนวณเรต" | E41: -ระบบแสดง error "กรอกจำนวนผู้ติดตาม หรือยอดวิวเฉลี่ยอย่างน้อยหนึ่งค่า" | F41: Negative | G41: Low | L41: Not Start
A42: เตือน Exclusivity ชนกัน
A43: ="TC_Creator_Dee_"&(ROW()-ROW($A$12)+1-4) -> TC_Creator_Dee_28 | B43: ตรวจสอบเมนู : ห้ามรับคู่แข่ง (Exclusivity) Field "ตั้งแต่" กรณี User เลือก "ปี ย้อนหลัง" แต่ Field "ถึง" เลือก "ปี ปัจจุบัน" และกดปุ่ม "เพิ่มดิล" ระบบแสดงหน้าจอถูกต้อง เงื่อนไข - Field "ตั้งแต่" : เลือก "ปี ย้อนหลัง" - Field "ถึง" : เลือก "ปี ปัจจุบัน" - กดปุ่ม : "เพิ่มดิล" | E43: -ระบบสร้างดีลสำเร็จรายการแสดงที่หน้า "ดีล" ถูกต้อง และแสดง หมายเหตุ : exclusivity | F43: Negative | G43: Medium | L43: Not Start
A44: ="TC_Creator_Dee_"&(ROW()-ROW($A$12)+1-4) -> TC_Creator_Dee_29 | B44: ตรวจสอบเมนู : ห้ามรับคู่แข่ง (Exclusivity) กรณี ดีลใหม่ชนกับดีลเดิม และแบรนด์เดียวกัน ช่วงเวลาลงงานชนกับช่วงห้ามรับคู่แข่ง (Exclusivity) ระบบ error ถูกต้อง เงื่อนไข -สร้างดีลใหม่หมวด "สกินแคร์" -วันลงงาน / เผยแพร่ : 20 ก.ค 2569 -ห้ามรับคู่แข่ง (Exclusivity) : ไม่ใส่ | E44: -ระบบสร้างดีลใหม่สำเร็จ -แสดงรายการดีลถูกต้อง และแสดง หมายเหตุ : exclusivity | F44: Negative | G44: Medium | L44: Not Start
A45: ="TC_Creator_Dee_"&(ROW()-ROW($A$12)+1-4) -> TC_Creator_Dee_30 | B45: ตรวจสอบเมนู : ห้ามรับคู่แข่ง (Exclusivity) กรณี เป็นสินค้าคนละแบรนด์ แต่หมวดสินค้าเดียวกัน แต่ช่วงเวลาลงงานตรงกับช่วงห้ามรับคู่แข่ง (Exclusivity) ดีลเดิม ระบบแสดงหน้าจอถูกต้อง เงื่อนไข -ดีลเดิมช่วง หมวดหมู่ แฟชั่น (Exclusivity) : 15 ก.ค 2569 - 22 ก.ค 2569 -ดีลใหม่ หมวดหมู่ แฟชั่น : วันลงงาน 20 ก.ค 2569 -ดีลใหม่ไม่กำหนด (Exclusivity) | E45: -ระบบแสดง popup : Exclusivity ชนกัน -ดีลนี้ชนเงื่อนไขห้ามรับคู่แข่งของดีลเดิม: -XX · หมวดเดียวกัน · ช่วงห้าม 2026-07-XX – 2026-07-XX -ระบบแสดงปุ่ม : ยกเลิก -ระบบแสดงปุ่ม : รับต่อ (รับทราบความเสี่ยง) -ระบบแสดงรายการดีลถูกต้อง และแสดง หมายเหตุ : รับทราบเสี่ยง ดีลใหม่ที่เพิ่งสร้าง | F45: Negative | G45: Medium | L45: Not Start
A46: ="TC_Creator_Dee_"&(ROW()-ROW($A$12)+1-4) -> TC_Creator_Dee_31 | B46: ตรวจสอบเมนู : ห้ามรับคู่แข่ง (Exclusivity) กรณี ไม่ได้ระบุหมวดสินค้า สร้างดีลใหม่ ระบุหมวด "แฟชั่น" ช่วงเวลา (Exclusivity) ทับกันบางส่วน (วันสุดท้ายพอดี) ระบบแสดงหน้าจอถูกต้อง เงื่อนไข -ดีล หมวด "ไม่ระบุ" exclusivity : 22ก.ค 2569 - 28 ก.ค 2569 -สร้างดีลใหม่ : หมวด "แฟชั่น" - ช่วงเวลา exclusivity : 28 ก.ค 2569 -3 ส.ค 2569 | E46: -ไม่สามารถทำรายการได้ ระบบแสดง error ระบุ "เลือกหมวดที่ห้ามชน" | F46: Negative | G46: Medium | L46: Not Start
...

Sheet เอกสาร
B1: =HYPERLINK("#Document!A1", "Refer to sheet Document") -> Refer to sheet Document
A3: Total TC. | B3: =COUNTIF(A13:A217,"TC_*") -> 189
A4: Test Cases ID | B4: Test Case Description | C4: Pre-Conditions | D4: Test Step | E4: Expected Result | F4: Positive/Negative | G4: Priority | H4: Test Data | I4: Tester | J4: Execution Plan | K4: Execution date | L4: Test Result | M4: Remark
A10: Scenario : Case validations : เมนู "ใบเสนอราคา"
A11: Scenario : Case validations : เมนู "หลัก"
A12: ="TC_Creator_Dee_"&(ROW()-ROW($A$12)+1) -> TC_Creator_Dee_1 | B12: ตรวจสอบเมนู : หน้าหลัก กรณี : บัญชีที่ยังไม่มีข้อมูลดีลเลย ระบบแสดงตัวเลข 0 ในทุกกล่อง summary ระบบแสเดงหน้าจอถูกต้อง เงื่อนไข -กดเมนู : หน้าหลัก (บัญชีใหม่ ไม่มีดีล) | E12: -ระบบแสดงหน้า หลัก โดยยังไม่มีรายการ ดีล - ระบบแสดงตัวเลข 0 ในกล่อง summar รายได้เดือนนี้ / เงินค้าง / ดีลที่กำลังทำอยู่ | F12: Positive | G12: Medium | L12: Not Start
A13: ="TC_Creator_Dee_"&(ROW()-ROW($A$12)+1) -> TC_Creator_Dee_2 | B13: ตรวจสอบเมนู : หน้าหลัก กรณี : กด กล่อง summary "รายได้เดือนนี้" ระบบแสดงหน้าจอถูกต้อง (ยอดรวมดีลที่กดรับเงินแล้วในเดือนปัจจุบัน) เงื่อนไข -กดเมนู : หน้าหลัก -กด : "รายได้เดือนนี้" | E13: - ระบบแสดงพาไปหน้า สรุปการเงิน แสดงรายละเอียดถูกต้อง - ระบบแสดงกล่อง ยอดเงินเข้าจริง (หลังหัก ณ ที่จ่าย)/ ยอดเงินค้างรับรวม /หัก ณ ที่จ่ายสะสม - ระบบแสดง เครื่องมือภาษี ใบ 50 ทวิ/ รายจ่าย / เตรียมยื่นภาษี | F13: Positive | G13: Medium | L13: Not Start
A14: ="TC_Creator_Dee_"&(ROW()-ROW($A$12)+1) -> TC_Creator_Dee_3 | B14: ตรวจสอบเมนู : หน้าหลัก กรณี : กดกล่อง summary "เงินค้างรับ" ระบบแสดงหน้าจอถูกต้อง (ยอดรวมดีลสถานะรอรับเงินทั้งหมด) เงื่อนไข -กดเมนู : หน้าหลัก -กด : "เงินค้างรับ" | C14: Pre-Conditions | E14: - ระบบแสดงพาไปหน้า ดีล แสดงรายละเอียดถูกต้อง - ระบบแสดงรายการ ดีล สถานะ "รอจ่าย" ของแต่ละเดือน | F14: Positive | G14: Medium | L14: Not Start
A15: ="TC_Creator_Dee_"&(ROW()-ROW($A$12)+1) -> TC_Creator_Dee_4 | B15: ตรวจสอบเมนู : หน้าหลัก กรณี : กดกล่อง summary "ดีลที่กำลังทำ" ระบบแสดงจำนวนดีลในสถานะกำลังทำงานถูกต้อง เงื่อนไข -กดเมนู : หน้าหลัก -กด : "ดีลที่กำลังทำ" | C15: Pre-Conditions | E15: - ระบบแสดงพาไปหน้า ดีลทั้งหมดที่แสดงรายละเอียดถูกต้อง | F15: Positive | G15: Medium | L15: Not Start
A16: ="TC_Creator_Dee_"&(ROW()-ROW($A$12)+1) -> TC_Creator_Dee_5 | B16: ตรวจสอบเมนู : หน้าหลัก สิ่งที่ควรจัดการ กรณี มีรายการ ดีล > 3 รายการ โดยมีมรายละเอียดดังนี้ ระบบแสดงหน้าจอถูกต้อง เงื่อนไข -กดเมนู : หน้าหลัก -มีรายการ ดีล : ใกล้ / เลยนัดส่งสคริป์ต 1 รายการ -มีรายการ ดีล : ใกล้ / เลย นัดส่ง draft > 1 รายการ -มีรายการ ดีล : อยู่ในช่วง เตือน Exclusivity 2 รายการ -มีรายการ ดีล : จ่ายเงินแล้ว แต่ยังไม่ออกเอกสาร | E16: - ระบบแสดงรายการ ดีล แต่ละหัวข้อได้ถูกต้อง | F16: Positive | G16: Medium | L16: Not Start
A17: ="TC_Creator_Dee_"&(ROW()-ROW($A$12)+1) -> TC_Creator_Dee_6 | B17: ตรวจสอบเมนู : หน้าหลัก มีรายการ "สิ่งที่ควรจัดการ" สถานะ "ด่วนมาก" กรณี กดที่ ปุ่ม : "ดูดีล" ระบบแสดงหน้าจอถูกต้อง เงื่อนไข -กดเมนู : หน้าหลัก -กดปุ่ม : ดูดีล | C17: Pre-Conditions | E17: -ระบบพาไปหน้าเมนู : ดีล แสดงรายละเอียด ดีล ทั้งหมดถูกต้อง | F17: Positive | G17: Medium | L17: Not Start
A18: ="TC_Creator_Dee_"&(ROW()-ROW($A$12)+1) -> TC_Creator_Dee_7 | B18: ตรวจสอบเมนู : หน้าหลัก มีรายการ "สิ่งที่ควรจัดการ" สถานะ "ด่วนมาก" กรณี กดที่ ปุ่ม : "เลื่อนเตือน อีก 3 วัน " ระบบแสดงหน้าจอถูกต้อง เงื่อนไข -กดเมนู : หน้าหลัก -กดปุ่ม :เลื่อนเตือน -popup : เลือก อีก 3 วัน -กดปุ่ม : เลื่อน | C18: Pre-Conditions | E18: -ระบบแสดง popup : เลื่อนเตือน "ซ่อนรายการนี้ไว้ก่อน แล้วเตือนอีกครั้งใน" -แสดงปุ่ม : ยกเลิก , เลื่อน - รายการ ดีล "ดีลด่วน" หายไปจากหน้า หลัก | F18: Positive | G18: Medium | H18: กางเคสระยะเวลาที่จะตกแต่ละสถานะ | L18: Not Start
A19: ="TC_Creator_Dee_"&(ROW()-ROW($A$12)+1) -> TC_Creator_Dee_8 | B19: ตรวจสอบเมนู : หน้าหลัก มีรายการ "สิ่งที่ควรจัดการ" สถานะ "ด่วนมาก" กรณี กดที่ ปุ่ม : "หลังคบกำหนด ลื่อนเตือน 3 วัน แล้ว " ระบบแสดงหน้าจอถูกต้อง เงื่อนไข -กดเมนู : หน้าหลัก | C19: Pre-Conditions | E19: -ระบบแสดง รายการ ดีล "ดีลด่วน" ที่เลื่อนเตือนไปแสดงรายการดีลถูกต้อง | F19: Positive | G19: Medium | L19: Not Start
A20: ="TC_Creator_Dee_"&(ROW()-ROW($A$12)+1) -> TC_Creator_Dee_9 | B20: ตรวจสอบเมนู : หน้าหลัก กรณี : มีดีลรับเงินคาบเกี่ยวช่วงเปลี่ยนเดือน (ปลายเดือน/ ต้นเดือนถัดไป) ระบบตัดยอด "รายได้เดือนนี้" ตามรอบเดือนปฏิทิน อิงเขตเวลาไทย (GMT+7) ถูกต้อง เงื่อนไข -มีดีลที่รับเงินวันสุดท้ายของเดือน และวันแรกของเดือนถัดไป -กดเมนู : หน้าหลัก | F20: Positive | G20: Medium | L20: Not Start
A21: ="TC_Creator_Dee_"&(ROW()-ROW($A$12)+1) -> TC_Creator_Dee_10 | B21: ตรวจสอบเมนู : หน้าหลัก มีรายการ "สิ่งที่ควรจัดการ" กรณี กดที่ ปุ่ม : "รับทราบ" ระบบแสดงหน้าจอถูกต้อง เงื่อนไข -กดเมนู : หน้าหลัก | C21: Pre-Conditions | E21: -ระบบแสดง รายการ ดีล "ดีลด่วน" ที่เลื่อนเตือนไปแสดงรายการดีลถูกต้อง | F21: Positive | G21: Medium | L21: Not Start
A22: Scenario : Case validations : เมนู "ดีล"
A23: บันทึกดีลเข้าระบบ
A24: ="TC_Creator_Dee_"&(ROW()-ROW($A$12)+1-2) -> TC_Creator_Dee_11 | B24: ตรวจสอบเมนู : ดีล กรณี "ยังไม่มีรายการดีล" ระบบและแสดงรายการทั้งหมดถูกต้อง เงื่อนไข - กดเมนู : ดีล | E24: -ระบบแสดงหน้า ดีล ถูกต้อง โดยแสดงช่อง คเนหาชื่อประเภทแบรน์ด / drop down ปี / drop down หมวดหมู่สิ้นค้า / drop down สถานะ - แสดงปุ่ม "ล้าง" -แสดงปุ่ม "Export" -แสดงปุ่ม "เพิ่มดิล" | F24: Positive | G24: High | L24: Not Start
A25: ="TC_Creator_Dee_"&(ROW()-ROW($A$12)+1-2) -> TC_Creator_Dee_12 | B25: ตรวจสอบเมนู : ดีล กรณี กดปุ่ม "เพิ่มดีล" User กรอกข้อมูลครบทุก Field และ ไม่กด "ช่วยคิดเรต" ระบบสร้างดีลสำเร็จ และแสดงรายการทั้งหมดถูกต้อง เงื่อนไข - กดเมนู : ดีล - กดปุ่ม : เพิ่มดีล - กรอกข้อมูลครบทุก Field : กด "เพิ่มดีล" | E25: -ระบบสร้างดีลสำเร็จรายการแสดงที่หน้า "ดีล" -ระบบแสดงสถานะ "ทาบทาม" ถูกต้อง | F25: Positive | G25: High | L25: Not Start
A26: ="TC_Creator_Dee_"&(ROW()-ROW($A$12)+1-2) -> TC_Creator_Dee_13 | B26: ตรวจสอบเมนู : ดีล กดปุ่ม "เพิ่มดีล" กรณี User ไม่กรอกชื่อแบรนด์ และกดปุ่ม "เพิ่มดีล" ระบบ error ถูกต้อง เงื่อนไข - Field ชื่อแบรนด์ : ไม่กรอกข้อมูล - กด "เพิ่มดีล" | C26: Pre-Conditions | E26: -ระบบแสดง error : " ใส่ชื่อแบรนด์" ใต้ Field ถูกต้อง | F26: Negative | G26: High | L26: Not Start
A27: ="TC_Creator_Dee_"&(ROW()-ROW($A$12)+1-2) -> TC_Creator_Dee_14 | B27: ตรวจสอบเมนู : ดีล กดปุ่ม "เพิ่มดีล" กรณี ไม่กรอกประเภทงาน และกดปุ่ม "เพิ่มดีล" ระบบ error ถูกต้อง เงื่อนไข - กดเมนู : ดีล - กดปุ่ม : เพิ่มดีล - Field ประเภทงาน : ไม่กรอกข้อมูล - กด "เพิ่มดีล" | C27: Pre-Conditions | E27: -ระบบแสดง error : " ใส่ประเภทงาน" ใต้ Field ถูกต้อง | F27: Negative | G27: High
A28: ="TC_Creator_Dee_"&(ROW()-ROW($A$12)+1-2) -> TC_Creator_Dee_15 | B28: ตรวจสอบเมนู : ดีล กดปุ่ม "เพิ่มดีล" กรณี ไม่กรอก Field "ข้อมูลผู้ติดต่อ /หมวดสินค้า" และกดปุ่ม "เพิ่มดีล" ระบบ error ถูกต้อง เงื่อนไข - กดเมนู : ดีล - กดปุ่ม : เพิ่มดีล - Field "ข้อมูลผู้ติดต่อ /หมวดสินค้า" : ไม่กรอก - กด "เพิ่มดีล" | C28: Pre-Conditions | E28: -ระบบสร้างดีลสำเร็จรายการแสดงที่หน้า "ดีล" -ระบบแสดงสถานะ "ทาบทาม" ถูกต้อง | F28: Negative | G28: High | L28: Not Start
A29: ="TC_Creator_Dee_"&(ROW()-ROW($A$12)+1-2) -> TC_Creator_Dee_16 | B29: ตรวจสอบเมนู : ดีล กดปุ่ม "เพิ่มดีล" กรณี User สร้างดีลชื่อแบรนด์ซ้ำ "เพิ่มดีล" ระบบ เงื่อนไข - กดเมนู : ดีล - กดปุ่ม : เพิ่มดีล - Field ชื่อแบรนด์ : กรอกชื่อแบรนด์ซ้ำ - กด "เพิ่มดีล" | E29: -ระบบสร้างดีลสำเร็จรายการแสดงที่หน้า "ดีล" -ระบบแสดงสถานะ "ทาบทาม" ถูกต้อง | F29: Positive | G29: Medium | H29: -ระบบสร้างชื่อแบร์นดซ้ำได้ | L29: Not Start
A30: ="TC_Creator_Dee_"&(ROW()-ROW($A$12)+1-2) -> TC_Creator_Dee_17 | B30: ตรวจสอบเมนู : ดีล กดปุ่ม "เพิ่มดีล" กรณี ปิดหน้า "เพิ่มดีล" กลางคันระหว่างกรอก ระบบแสดงหน้าจอถูกต้อง เงื่อนไข - กดเมนู : ดีล - กดปุ่ม : เพิ่มดีล - All field : กรอกข้อมูลครบทุก - กด : "X" | E30: -ระบบสร้างดีลไม่สำเร็จและไม่มีรายการใหม่แสดงที่หน้า "ดีล" | F30: Positive | G30: Medium | L30: Not Start
A31: ="TC_Creator_Dee_"&(ROW()-ROW($A$12)+1-2) -> TC_Creator_Dee_18 | B31: ตรวจสอบเมนู : ดีล กดปุ่ม "เพิ่มดีล" กรณีกรอกข้อมูล Field : ชื่อแบรนด์ * / ประเภทงาน * / ช่องทางที่ติดต่อ / ราคา (บาท) ครบถ้วน และกด เมนู "ช่วยคิดเรต" ระบบหน้าจอถูกต้อง เงื่อนไข - กดเมนู : ดีล - กดปุ่ม : เพิ่มดีล - All field : กรอกข้อมูลครบทุก - กด : "ช่วยคิดเรต" | E31: -ระบบพาไปหน้า "ประเมินราคางานที่ควรเสนอ" ถูกต้อง | F31: Positive | G31: Medium | L31: Not Start
A32: ="TC_Creator_Dee_"&(ROW()-ROW($A$12)+1-2) -> TC_Creator_Dee_19 | B32: ตรวจสอบเมนู : ดีล กดปุ่ม "เพิ่มดีล" กรณี ไม่กรอกข้อมูล Field ทั้งหมด และกดปุ่ม "ช่วยคิดเรต" ระบบหน้าจอถูกต้อง เงื่อนไข - All field : ไม่กรอกข้อมูล - กด : "ช่วยคิดเรต" | E32: -ระบบแสดง error : "กรอกจำนวนผู้ติดตาม หรือยอดวิวเฉลี่ยอย่างน้อยหนึ่งค่า" ถูกต้อง | F32: Negative | G32: High | L32: Not Start
A33: ="TC_Creator_Dee_"&(ROW()-ROW($A$12)+1-2) -> TC_Creator_Dee_20 | B33: ตรวจสอบเมนู : ดีล กดปุ่ม "เพิ่มดีล" กรณี : User มีการสร้างดีลโดยมีเพียง วันที่นัดส่งสคริปต์ให้แบรนด์รีวิว และยังห่างจากวันปัจจุบันเกิน 3 วัน เงื่อนไข - วันที่นัดส่งสคริปต์ให้แบรนด์รีวิว > (Current date + 3 วัน) | F33: Positive | G33: Medium | L33: Not Start | M33: TC_Calendar_2
A34: ="TC_Creator_Dee_"&(ROW()-ROW($A$12)+1-2) -> TC_Creator_Dee_21 | B34: ตรวจสอบเมนู : ดีล กดปุ่ม "เพิ่มดีล" กรณี : สร้างดีลโดยมีเพียง วันที่นัดส่งสคริปต์ให้แบรนด์รีวิว และเกือบจะถึง deadline แล้ว (<= 3 วัน) เงื่อนไข - วันที่นัดส่งสคริปต์ให้แบรนด์รีวิว <= (Current date + 3 วัน) แต่ไม่ต่ำกว่า Current Date | F34: Positive | G34: Medium | L34: Not Start | M34: TC_Calendar_3
A35: ="TC_Creator_Dee_"&(ROW()-ROW($A$12)+1-2) -> TC_Creator_Dee_22 | B35: ตรวจสอบเมนู : ดีล กดปุ่ม "เพิ่มดีล" กรณี : สร้างดีลโดยมีเพียง วันที่นัดส่งสคริปต์ให้แบรนด์รีวิว แต่เลย deadline แล้ว (< Current date) เงื่อนไข - วันที่นัดส่งสคริปต์ให้แบรนด์รีวิว < (Current date) | F35: Positive | G35: Medium | L35: Not Start | M35: TC_Calendar_4
A36: ="TC_Creator_Dee_"&(ROW()-ROW($A$12)+1-2) -> TC_Creator_Dee_23 | B36: ตรวจสอบเมนู : ดีล กดปุ่ม "เพิ่มดีล" กรณี : สร้างดีลโดยมีเพียง วันที่นัดส่ง draft / งาน และยังห่างจากวันปัจจุบันเกิน 3 วัน เงื่อนไข - วันที่นัดส่ง draft / งาน > (Current date + 3 วัน) | F36: Positive | G36: Medium | L36: Not Start | M36: TC_Calendar_5
A37: ="TC_Creator_Dee_"&(ROW()-ROW($A$12)+1-2) -> TC_Creator_Dee_24 | B37: ตรวจสอบเมนู : ดีล กดปุ่ม "เพิ่มดีล" กรณี : สร้างดีลโดยมีเพียง วันที่นัดส่ง draft / งาน และเกือบจะถึง deadline แล้ว (<= 3 วัน) - วันที่นัดส่ง draft / งาน <= (Current date + 3 วัน) แต่ไม่ต่ำกว่า Current Date | F37: Positive | G37: Medium | L37: Not Start | M37: TC_Calendar_6
A38: ="TC_Creator_Dee_"&(ROW()-ROW($A$12)+1-2) -> TC_Creator_Dee_25 | B38: ตรวจสอบเมนู : ดีล กดปุ่ม "เพิ่มดีล" กรณี : User มีการสร้างดีลโดยมีเพียง วันที่นัดส่ง draft / งาน แต่เลย deadline แล้ว (< Current date) - วันที่นัดส่ง draft / งาน < (Current date) | F38: Positive | G38: Medium | L38: Not Start | M38: TC_Calendar_7
A39: ="TC_Creator_Dee_"&(ROW()-ROW($A$12)+1-2) -> TC_Creator_Dee_26 | B39: ตรวจสอบเมนู : ดีล กดปุ่ม "เพิ่มดีล" กรณี : User มีการสร้างดีลโดยมีเพียง วันลงงาน / เผยแพร่ และยังห่างจากวันปัจจุบันเกิน 3 วัน - วันที่นัดส่ง draft / งาน > (Current date + 3 วัน) | F39: Positive | G39: Medium | L39: Not Start | M39: TC_Calendar_8
A40: ="TC_Creator_Dee_"&(ROW()-ROW($A$12)+1-2) -> TC_Creator_Dee_27 | B40: ตรวจสอบเมนู : ดีล กดปุ่ม "เพิ่มดีล" กรณี : User มีการสร้างดีลโดยมีเพียง วันลงงาน / เผยแพร่ และเกือบจะถึง deadline แล้ว (<= 3 วัน) - วันลงงาน / เผยแพร่ <= (Current date + 3 วัน) แต่ไม่ต่ำกว่า Current Date | F40: Positive | G40: Medium | L40: Not Start | M40: TC_Calendar_9
A41: ="TC_Creator_Dee_"&(ROW()-ROW($A$12)+1-2) -> TC_Creator_Dee_28 | B41: ตรวจสอบเมนู : ดีล กดปุ่ม "เพิ่มดีล" กรณี : User มีการสร้างดีลโดยมีเพียง วันลงงาน / เผยแพร่ แต่เลย deadline แล้ว (< Current date) - วันลงงาน / เผยแพร่ < (Current date) | F41: Positive | G41: Medium | L41: Not Start | M41: TC_Calendar_10
A42: ="TC_Creator_Dee_"&(ROW()-ROW($A$12)+1-2) -> TC_Creator_Dee_29 | B42: ตรวจสอบเมนู : ดีล Field "วันที่นัดส่งสคริปต์ให้แบรนด์รีวิว" เกรณี กรอกข้อมูล "ปีย้อนหลัง" และกดปุ่ม "เพิ่มดิล" ระบบแสดงหน้าจอถูกต้อง เงื่อนไข -Field วันที่นัดส่งสคริปต์ให้แบรนด์รีวิว : ปี (2568) | E42: -ระบบสร้างดีลสำเร็จรายการแสดงที่หน้า "ดีล" -ระบบแสดงสถานะ "ทาบทาม" ถูกต้อง | F42: Negative | G42: High | L42: Not Start
A43: ="TC_Creator_Dee_"&(ROW()-ROW($A$12)+1-2) -> TC_Creator_Dee_30 | B43: ตรวจสอบเมนู : ดีล กดปุ่ม "เพิ่มดีล" Field "วันที่นัดส่ง draft / งาน" กรณี กรอกข้อมูล "เดือนไม่ใช่เดือนปุจจุบัน" และกดปุ่ม "เพิ่มดิล" ระบบแสดงหน้าจอถูกต้อง เงื่อนไข -Field วันที่นัดส่ง draft / งาน : เดือนไม่ใช่เดือนปุจจุบัน | E43: -ระบบสร้างดีลสำเร็จรายการแสดงที่หน้า "ดีล" -ระบบแสดงสถานะ "ทาบทาม" ถูกต้อง | F43: Negative | G43: High | L43: Not Start
A44: ="TC_Creator_Dee_"&(ROW()-ROW($A$12)+1-2) -> TC_Creator_Dee_31 | B44: ตรวจสอบเมนู : ดีล กดปุ่ม "เพิ่มดีล" กำหนดการ & การจ่ายเงิน Field "วันลงงาน / เผยแพร่" กรณี กรอกข้อมูล "วันที่ย้อนหลัง" "เพิ่มดิล" ระบบแสดงหน้าจอถูกต้อง เงื่อนไข -Field วันลงงาน / เผยแพร่ :"วันที่ย้อนหลัง" | E44: -ระบบสร้างดีลสำเร็จรายการแสดงที่หน้า "ดีล" -ระบบแสดงสถานะ "ทาบทาม" ถูกต้อง | F44: Negative | G44: High | L44: Not Start
A45: ="TC_Creator_Dee_"&(ROW()-ROW($A$12)+1-2) -> TC_Creator_Dee_32 | B45: ตรวจสอบเมนู : ดีล กดปุ่ม "เพิ่มดีล" กำหนดการ & การจ่ายเงิน Field "กำหนดจ่ายเงิน" กรณี กรอกข้อมูล "ปีย้อนหลัง" และกดปุ่ม "เพิ่มดิล"ระบบแสดงหน้าจอถูกต้อง เงื่อนไข -Field "กำหนดจ่ายเงิน" : วันที่/เดือน/ ปี ย้อนหลัง | E45: -ระบบสร้างดีลสำเร็จรายการแสดงที่หน้า "ดีล" -ระบบแสดงสถานะ "ทาบทาม" ถูกต้อง | F45: Negative | G45: High | L45: Not Start
A46: ="TC_Creator_Dee_"&(ROW()-ROW($A$12)+1-2) -> TC_Creator_Dee_33 | B46: ตรวจสอบเมนู : เพิ่มดีล และ กดปุ่ม "ช่วยคิดเรต" กรณี กรอกยอด Engagement ทั้งหมด แล้วกด "คำนวณเรต"ระบบแสดงหน้าจอถูกต้อง เงื่อนไข - กด : ช่วยคิดเรต - Field ไลก์ : 5,000 - Field คอมเมนต์ : 100 - Field เซฟ : 1,000 - Filed แชร์ : 550 - กดปุ่ม : "คำนวณเรต" | E46: -ระบบคำนวณคิดเรตงานจากยอด Engagement ได้ถูกต้อง -ระบบแสดงยอด ราคาที่แนะนำ 3 ราคามาให้เลือก : Low/Market / Premium | F46: Positive | G46: High | L46: Not Start
...

Sheet ชีต5
A2: status | B2: แก้ไขดีล | C2: ปฎิทิน | D2: status หน้า ดีล | E2: หน้าหลัก
A3: ทาบทาม | B3: Field : วันที่นัดส่ง draft / งาน | C3: = Current date | D3: ใกล้ deadline | E3: ด่วนมาก
B4: "Mac | C4: > Current date 3 day | D4: ใกล้ deadline | E4: ด่วนมาก
B5: "น้ำหอม | C5: < Current date 7 day | D5: Null | E5: Null
B6: "น้ำหอม. แก้ไข field >> วันที่นัดส่งสคริปต์ให้แบรนด์รีวิว | C6: > Current date 7 day | D6: Null | E6: ด่วนมาก
A11: กำลังทำงาน = Facebook กรอกแค่ "กำหนดจ่ายเงิน" | C11: แสดงหับข้อ ไม่ระบุเดือน
A12: กำลังทำงาน = Mac กรอกแค่ "วันที่นัดส่งสคริปต์ให้แบรนด์รีวิว" | C12: แสดงหับข้อ ไม่ระบุเดือน
A13: test = วันลงงาน / เผยแพร่ | C13: ปรากฎเดือนปกติ
A18: status : ตกลงราคา -----> จับแท้ก status จาก Field : วันที่นัดส่ง draft / งาน
A19: status : รอจ่าย -----> จับแท้ก status จาก Field : กำหนดจ่ายเงิน
A28: ="TC_Creator_Dee_"&(ROW()-ROW($A$12)+1-4) -> TC_Creator_Dee_13 | B28: ตรวจสอบเมนู : ห้ามรับคู่แข่ง (Exclusivity) กรณี แก้ไข "วันที่นัดส่ง draft / งาน" ของดีล A ให้ตรงกับช่วง Exclusivity ของดีลอื่น (หมวดเดียวกัน) โดยแก้ไขสถานะ "ทามทาม ---> "ตกลงราคา"ระบบแสดงหน้าจอถูกต้อง เงื่อนไข -เปลี่ยนสถานะดีล A จาก "ทาบทาม" → "ตกลงราคา" -เปิดรายละเอียดดีล A -แก้ไข "วันที่นัดส่ง draft / งาน " ให้ตกอยู่ในช่วง Exclusivity ของดีล B ( > Current date 3 วัน)) -กดบันทึก | E28: -ระบบแสดง popup : Exclusivity ชนกัน -ดีลนี้ชนเงื่อนไขห้ามรับคู่แข่งของดีลเดิม: -XX · หมวดเดียวกัน · ช่วงห้าม 2026-07-XX – 2026-07-XX -ระบบแสดงปุ่ม : ยกเลิก -ระบบแสดงปุ่ม : รับต่อ (รับทราบความเสี่ยง) -ระบบแสดงรายการดีลถูกต้อง และแสดง หมายเหตุ : รับทราบเสี่ยง ดีลใหม่ที่เพิ่งสร้าง | F28: Positive | G28: Medium | L28: Not Start
A29: ="TC_Creator_Dee_"&(ROW()-ROW($A$12)+1-5) -> TC_Creator_Dee_13 | E29: หน้าหลัก -ระบบแสดงรายการ : สิ่งที่ควรจัดการ ใกล้นัดส่ง สคริปต์ · status : ด่วน หน้าดีล -ระบบแสดงรายการสถานะ ดีล ที่หน้า ดีลถูกต้อง -แสดงรายการ ดีล อยุ่ใน หมวด : ระบุเดือน -โดยแสดง หมายเหตุ : รอส่ง Draft | F29: Positive | G29: High | L29: Not Start
A30: ="TC_Creator_Dee_"&(ROW()-ROW($A$12)+1-5) -> TC_Creator_Dee_14 | B30: ตรวจสอบเมนู : "แก้ไข" กรณี User : แก้ไข วันที่นัดส่ง draft / งาน < (Current date 3 วัน) แต่เลย deadline แล้ว โดย กดเปลี่ยน status : "ทาบทาม" ---> "ตกลงราคา" เงื่อนไข - วันที่นัดส่ง draft / งาน : < (Current date 3 วัน) เลย deadline แล้ว - กดเปลี่ยนสถานะดีล : "ตกลงราคา" ---> "อยู่ในระหว่างทำงาน" FYI : ใช้ข้อมูลแก้ไขจากข้อม 53 | E30: หน้าหลัก -ระบบแสดงรายการ : สิ่งที่ควรจัดการ ใกล้นัดส่ง สคริปต์ · status : ด่วนมาก หน้าดีล -ระบบแสดงรายการสถานะ ดีล ที่หน้า ดีลถูกต้อง -แสดงรายการ ดีล อยุ่ใน หมวด : ระบุเดือน -โดยแสดง หมายเหตุ : เลยกำหนดส่งงาน , รอส่ง Draft | F30: Positive | G30: High | L30: Not Start
A31: ="TC_Creator_Dee_"&(ROW()-ROW($A$12)+1-5) -> TC_Creator_Dee_15 | B31: ตรวจสอบเมนู : "แก้ไข" กรณี User : แก้ไข กำหนดจ่ายเงิน > (Current date 3 วัน) แต่เลย deadline แล้ว โดย กดเปลี่ยน status : "ตกลงราคา" ---> "รอจ่าย" เงื่อนไข - กำหนดจ่ายเงิน > (Current date 3 วัน) - กดเปลี่ยนสถานะดีล : "ตกลงราคา" ---> "รอจ่าย" FYI : ใช้ข้อมูลแก้ไขจากข้อม 54 | E31: หน้าหลัก -ระบบแสดงรายการ : เงินที่ควรติดตาม · status : ปานกลาง หน้าดีล -ระบบแสดงรายการสถานะ ดีล ที่หน้า ดีลถูกต้อง -แสดงรายการ ดีล อยุ่ใน หมวด : ระบุเดือน -โดยแสดง หมายเหตุ : เลยกำหนดส่งงาน , รอส่ง Draft | F31: Positive | G31: High | L31: Not Start
A32: ="TC_Creator_Dee_"&(ROW()-ROW($A$12)+1-5) -> TC_Creator_Dee_16 | B32: ตรวจสอบเมนู : "แก้ไข" กรณี User : แก้ไข โดย กดเปลี่ยน status : "รอจ่าย" ---> "รับเงิน" เงื่อนไข - กดเปลี่ยนสถานะดีล : "รอจ่าย" ---> "รับเงิน" - รับเงินเติมจำนวน - ไม่หัก - กดปุ่ม "บันทึกรับเงิน" FYI : ใช้ข้อมูลแก้ไขจากข้อม 55 | E32: -ระบบแสดง popup : ออกใบเสร็จ? บันทึกรับเงินแล้ว — ออกใบเสร็จรับเงิน ฿10000 ให้แบรนด์เลยไหม? -แสดงปุ่ม : ยกเลิก -แสดงปุ่ม : ออกใบเสร็จ -ระบบพาไปหน้า "ใบเสร็จรับเงิน" | F32: Positive | G32: High | L32: Not Start

Sheet Create_content
B1: =HYPERLINK("#Document!A1", "Refer to sheet Document") -> Refer to sheet Document
A3: Total TC. | B3: =COUNTIF(A11:A117,"TC_*") -> 47
A4: Test Cases ID | B4: Test Case Description | C4: Pre-Conditions | D4: Test Step | E4: Expected Result | F4: Positive/Negative | G4: Priority | H4: Test Data | I4: Tester | J4: Execution Plan | K4: Execution date | L4: Test Result | M4: Remark
A10: CreatorDee
A11: Scenario : Case validations สร้างคอนเทนต์
A12: ="TC_Create_content_"&(ROW()-ROW($A$12)+1) -> TC_Create_content_1 | B12: ตรวจสอบเมนู : สร้างคอนเทนต์ กรณี "ตรวจสอบหน้าจอและเมนูทั้งหมด" ระบบแสดงหน้าจอถูกต้อง เงื่อนไข - กดปุ่ม : สร้างคอนเทนต์ | E12: - ระบบแสดง เมนู : คลังไวรัล , สร้างคลิป , บอร์ดคอนเทนต์ , สไตล์คุณ - แท็บ "คลังไวรัล" ถูกไฮไลต์ (สีน้ำเงิน) เป็นค่าเริ่มต้น - ระบบแสดงช่อง "ค้นหา" ถูกต้อง รองรับ ภาษาไทยและ ภาษาอังกฤษ - ระบบแสดง drop down ให้เลือกดังนี้ - วิวมากสุด - ไลก์มากสุด - คอมเมนต์มากสุด - เซฟมากสุด - เอนเกจสูงสุด - Outlier สูงสุด - ใหม่สุด - สั้นสุด | F12: Positive | G12: Medium | L12: Not Start
A13: ="TC_Create_content_"&(ROW()-ROW($A$12)+1) -> TC_Create_content_2 | B13: ตรวจสอบเมนู : สร้างคอนเทนต์ ช่อง Sarch : คอนเทนต์ ด้วยแคปชัน เช่น "millionaire" ระบบแสดงหน้าจอถูกต้อง เงื่อนไข - กดปุ่ม : สร้างคอนเทนต์ - ช่อง Sarch : "millionaire" | E13: - ระบบแสดงคลิปคอนเทนต์ที่มีคำนั้นในแคปชันเท่านั้น | F13: Positive | G13: Low | L13: Not Start
A14: ="TC_Create_content_"&(ROW()-ROW($A$12)+1) -> TC_Create_content_3 | B14: ตรวจสอบเมนู : สร้างคอนเทนต์ ช่อง Sarch : ค้นหาด้วยชื่อช่อง "@brittanyybowen" ระบบแสดงหน้าจอถูกต้อง เงื่อนไข - กดปุ่ม : สร้างคอนเทนต์ - ช่อง Sarch : @brittanyybowen | E14: - ระบบแสดงคลิปคอนเทนต์ของครีเอเตอร์นั้นเท่านั้น | F14: Positive | G14: Low | L14: Not Start
A15: ="TC_Create_content_"&(ROW()-ROW($A$12)+1) -> TC_Create_content_4 | B15: ตรวจสอบเมนู : สร้างคอนเทนต์ ช่อง Sarch : คอนเทนต์ "ภาษาไทย " ด้วยหมวดหมู่ ระบบแสดงหน้าจอถูกต้อง เงื่อนไข - กดปุ่ม : สร้างคอนเทนต์ - ช่อง Sarch : ความสวยความงาม | E15: - ระบบแสดงคลิปคอนเทนต์จากหมวดหมู่ที่ค้นหาเท่านั้น | F15: Positive | G15: Low | L15: Not Start
A16: ="TC_Create_content_"&(ROW()-ROW($A$12)+1) -> TC_Create_content_5 | B16: ตรวจสอบเมนู : สร้างคอนเทนต์ ช่อง Sarch : คอนเทนต์ "ผลลัพธ์พิมพ์คำที่ไม่มีในระบบ" ด้วยหมวดหมู่ ระบบแสดงหน้าจอถูกต้อง เงื่อนไข - กดปุ่ม : สร้างคอนเทนต์ - ช่อง Sarch : สกินแคร์ | E16: -ระบบแสดงข้อความ "ไม่พบคลิปที่ตรงกับ XXX" | F16: Positive | G16: Low | L16: Not Start
A17: ="TC_Create_content_"&(ROW()-ROW($A$12)+1) -> TC_Create_content_6 | B17: ตรวจสอบเมนู : สร้างคอนเทนต์ กรณี drop down "แชร์มากสุด" + Sarch ระบบแสดงหน้าจอถูกต้อง เงื่อนไข - กดปุ่ม : สร้างคอนเทนต์ - ช่อง Sarch : การเงิน + drop down "แชร์มากสุด" | E17: -ระบบแสดงผลลัพธ์ถูกกรองและเรียงลำดับถูกต้องพร้อมกันทั้งสองเงื่อนไข | F17: Positive | G17: Low | L17: Not Start
A18: ="TC_Create_content_"&(ROW()-ROW($A$12)+1) -> TC_Create_content_7 | B18: ตรวจสอบเมนู : สร้างคอนเทนต์ กรณี คลิกปุ่ม "ที่บันทึกไว้ 0" (ยังไม่มีการบันทึก) ระบบแสดงหน้าจอถูกต้อง เงื่อนไข - กดปุ่ม : สร้างคอนเทนต์ - กดปุ่ม "ที่บันทึกไว้" | E18: -ระบบแสดง empty state เนื่องจากยังไม่มีคลิปที่บันทึก | F18: Positive | G18: Low | L18: Not Start
A19: ="TC_Create_content_"&(ROW()-ROW($A$12)+1) -> TC_Create_content_8 | B19: ตรวจสอบเมนู : สร้างคอนเทนต์ กรณี คลิกปุ่ม "บันทึกคลิปแล้วเช็คจำนวน" ระบบแสดงหน้าจอถูกต้อง เงื่อนไข - กดปุ่ม : สร้างคอนเทนต์ -กดปุ่ม "กดไอคอนหัวใจที่การ์ดคลิป" - กดปุ่ม "ที่บันทึกไว้" | E19: -ตัวเลขเพิ่มขึ้น 1 และคลิปที่กดปรากฏในแท็บนี้ | F19: Positive | G19: Low | L19: Not Start
A20: ="TC_Create_content_"&(ROW()-ROW($A$12)+1) -> TC_Create_content_9 | B20: ตรวจสอบเมนู : สร้างคอนเทนต์ กรณี คลิกปุ่ม "ยกเลิกบันทึก (unfavorite)" ระบบแสดงหน้าจอถูกต้อง เงื่อนไข - กดปุ่ม : สร้างคอนเทนต์ -กดปุ่ม "กดหัวใจซ้ำที่คลิปที่บันทึกไว้แล้ว" | E20: -คลิปหายไปจากแท็บ "ที่บันทึกไว้" และตัวเลขลดลง | F20: Positive | G20: Low | L20: Not Start
A21: ="TC_Create_content_"&(ROW()-ROW($A$12)+1) -> TC_Create_content_10 | B21: ตรวจสอบเมนู : สร้างคอนเทนต์ กรณี "กดที่พื้นที่ว่างในคลิป" ระบบแสดงหน้าจอถูกต้อง เงื่อนไข - กดปุ่ม : สร้างคอนเทนต์ - กด : พื้นที่ว่างในคลิป | E21: - ระบบแสดงคลิปคอนเทนต์ popup ขึ้นมา แสดงชื่อ account , ปุ่ม "ปิด",ปุ่ม "นำไปสร้าง"ปุ่ม : "ดูคลิปต้นทาง" | F21: Positive | G21: Low | L21: Not Start
A22: ="TC_Create_content_"&(ROW()-ROW($A$12)+1) -> TC_Create_content_11 | B22: ตรวจสอบเมนู : สร้างคอนเทนต์ ช่อง Sarch : คอนเทนต์ "อักขระพิเศษ" ระบบแสดงหน้าจอถูกต้อง เงื่อนไข - กดปุ่ม : สร้างคอนเทนต์ - ช่อง Sarch : คอนเทนต์ "อักขระพิเศษ" | E22: - ระบบแสดงล๊อคไม่ให้ทำการกรอกข้อมูลค้นหาใน Field sarch ได้ | F22: Positive | G22: Low | L22: Not Start
A23: ="TC_Create_content_"&(ROW()-ROW($A$12)+1) -> TC_Create_content_12 | B23: ตรวจสอบเมนู : สร้างคอนเทนต์ ค้นหาคอนเทนต์ คลิก drop down "ไลก์มากที่สุด" ระบบแสดงหน้าจอถูกต้อง เงื่อนไข - กดปุ่ม : สร้างคอนเทนต์ - กดปุ่ม drop down : "ไลก์มากที่สุด" | E23: - ระบบแสดงคลิปคอนเทนต์จากหมวดหมู่ "ไลก์มากที่สุด" | F23: Positive | G23: Low | L23: Not Start
A24: ="TC_Create_content_"&(ROW()-ROW($A$12)+1) -> TC_Create_content_13 | B24: ตรวจสอบเมนู : สร้างคอนเทนต์ "เลือก Tab คลังไวรัล" กรณี กดปุ่ม "นำคลิปไปใช้" ระบบแสดงหน้าจอถูกต้อง เงื่อนไข - กดปุ่ม : สร้างคอนเทนต์ - กดปุ่ม : เลือก Tab คลังไวรัล - กดปุ่ม: นำคลิปไปใช้ | F24: Positive | G24: Medium | L24: Not Start
A25: ="TC_Create_content_"&(ROW()-ROW($A$12)+1) -> TC_Create_content_14 | B25: ตรวจสอบเมนู : สร้างคอนเทนต์ กรณี "เลือก Tab สร้างคลิป" ระบบแสดงหน้าจอถูกต้อง เงื่อนไข - กดปุ่ม : สร้างคอนเทนต์ - กดปุ่ม : เลือก Tab สร้างคลิป | F25: Positive | G25: Low | L25: Not Start
A26: ="TC_Create_content_"&(ROW()-ROW($A$12)+1) -> TC_Create_content_15 | B26: ตรวจสอบเมนู : สร้างคอนเทนต์ กรณี "เลือก Tab บอร์คอนเทนต์" ระบบแสดงหน้าจอถูกต้อง เงื่อนไข - กดปุ่ม : สร้างคอนเทนต์ - กดปุ่ม : เลือก Tab บอร์คอนเทนต์ | F26: Positive | G26: Low | L26: Not Start
A27: ="TC_Create_content_"&(ROW()-ROW($A$12)+1) -> TC_Create_content_16 | B27: ตรวจสอบเมนู : สร้างคอนเทนต์ กรณี "เลือก Tab สไตล์คุณ" ระบบแสดงหน้าจอถูกต้อง เงื่อนไข - กดปุ่ม : สร้างคอนเทนต์ - กดปุ่ม : เลือก Tab สไตล์คุณ | F27: Positive | G27: Low | L27: Not Start
A28: ="TC_Create_content_"&(ROW()-ROW($A$12)+1) -> TC_Create_content_17 | B28: ตรวจสอบเมนู : สร้างคอนเทนต์ โดยกดมาจาก เมนู "นำไปสร้าง" กรณี Field : หัวข้อคลิป "กรอกข้อมูลอักขระพิเศษ" ระบบล๊อค Field ไม่สามารถกรอกได้ เงื่อนไข -กดเมนู : นำไปสร้าง -Field : หัวข้อคลิป "กรอกข้อมูลอักขระพิเศษ" | E28: - ระบบแสดงล๊อคไม่ให้ทำการกรอกข้อมูลค้นหาใน Field sarch ได้ | F28: Negative | G28: Low | L28: Not Start
A29: ="TC_Create_content_"&(ROW()-ROW($A$12)+1) -> TC_Create_content_18 | B29: ตรวจสอบเมนู : สร้างคอนเทนต์ โดยกดมาจาก เมนู "นำไปสร้าง" กรณี Field : มุมที่อยากเน้น "กรอกข้อมูลอักขระพิเศษ" ระบบล๊อค Field ไม่สามารถกรอกได้ เงื่อนไข -กดเมนู : นำไปสร้าง -Field : มุมที่อยากเน้น "กรอกข้อมูลอักขระพิเศษ" | E29: - ระบบแสดงล๊อคไม่ให้ทำการกรอกข้อมูลค้นหาใน Field sarch ได้ | F29: Negative | G29: Low | L29: Not Start
A30: ="TC_Create_content_"&(ROW()-ROW($A$12)+1) -> TC_Create_content_19 | B30: ตรวจสอบเมนู :สร้างคอนเทนต์ โดยกดมาจาก เมนู "นำไปสร้าง" หัวข้อ "เป้าหมายคลิป" กรณี "กดเลือก Tab ในหัวข้อสูตรสร้าง" ระบบแสดงหน้าจอถูกต้อง เงื่อนไข -กดเมนู : นำไปสร้าง -หัวข้อ : สูตรสร้าง - กดเลือก Tab ต่างๆ | F30: Positive | G30: Low | L30: Not Start
A31: ="TC_Create_content_"&(ROW()-ROW($A$12)+1) -> TC_Create_content_20 | B31: ตรวจสอบเมนู : สร้างคลิป หัวข้อ ความยาว กรณี "กด Tab ความยาว " ระบบแสดงหน้าจอถูกต้อง เงื่อนไข -กดเมนู : นำไปสร้าง -หัวข้อ : ความยาว - กดเลือก Tab ต่างๆ | F31: Positive | G31: Low | L31: Not Start
A32: ="TC_Create_content_"&(ROW()-ROW($A$12)+1) -> TC_Create_content_21 | B32: ตรวจสอบเมนู : สร้างคอนเทนต์ "เลือก Tab คลังไวรัล กรณี "สร้างคอนเทนต์จากคลิปต้นแบบ" โดยมีรายละเอียดดังนี้ และ ระบบแสดงหน้าจอถูกต้อง เงื่อนไข - กดปุ่ม : สร้างคอนเทนต์ - เลือก : Tab คลังไวรัล - กดปุ่ม : นำไปสร้าง - หัวข้อคลิป : กรอกข้อมูล - มุมที่อยากเน้น : กรอกข้อมูล - เป้าหมายคลิป : ให้ความรู้ - สูตรสร้าง : อัตโนมัติ - ความยาว : 60 วิ | F32: Positive | G32: High | L32: Not Start
A33: ="TC_Create_content_"&(ROW()-ROW($A$12)+1) -> TC_Create_content_22 | B33: ตรวจสอบเมนู : สร้างคอนเทนต์ เลือก Tab คลังไวรัล สร้างคอนเทนต์จากคลิปต้นแบบ กรณี เลือก เป้าหมายคลิป "เล่าเรื่องสร้างตัวตน และความยาวคลิป 90 วิ" โดยมีรายละเอียดดังนี้ และ ระบบแสดงหน้าจอถูกต้อง เงื่อนไข - กดปุ่ม : สร้างคอนเทนต์ - เลือก : Tab คลังไวรัล - กดปุ่ม : นำไปสร้าง - หัวข้อคลิป : กรอกข้อมูล - มุมที่อยากเน้น : กรอกข้อมูล - เป้าหมายคลิป : เล่าเรื่องสร้างตัวตน - สูตรสร้าง : ทำนายเทรน - ความยาว : 90 วิ - กดปุ่ม : Generate | F33: Positive | G33: High | L33: Not Start
A34: ="TC_Create_content_"&(ROW()-ROW($A$12)+1) -> TC_Create_content_23 | B34: ตรวจสอบ กรณี หลังจากกดปุ่ม Generate ระบบสร้าง สคริปมาให้เลือกสูงสุด 3 แบบ และ "รายละเอียด beats" ในกล่องสคริป โดยมีรายละเอียดดังนี้ และ ระบบแสดงหน้าจอถูกต้อง เงื่อนไข - กดปุ่ม : ดู "รายละเอียด beats" ในกล่องสคริป | F34: Positive | G34: Medium | L34: Not Start
A35: ="TC_Create_content_"&(ROW()-ROW($A$12)+1) -> TC_Create_content_24 | B35: ตรวจสอบ กรณี เลือกสคริปต์ คะแนน A 9.0/10 กดปุ่ม "ใช้แบบนี้" ในกล่องสคริป ระบบแสดงหน้าจอถัดไปถูกต้อง เงื่อนไข - กดปุ่ม : ใช้แบบนี้ | F35: Positive | G35: Medium | L35: Not Start
A36: ="TC_Create_content_"&(ROW()-ROW($A$12)+1) -> TC_Create_content_25 | B36: ตรวจสอบ หน้า สคริปต์ กรณี กด ปุ่ม "คัดลอกสคริปต์" และ "กำหนดวันโพสต์ : วันที่ + 3 / เดือน/ ปี ปัจจุบัน " ระบบแสดงหน้าจอถูกต้อง เงื่อนไข - กดปุ่ม : คัดลอกสคริปต์ - กำหนดวันโพสต์ : วันที่ ปจจ + 3 / เดือน/ ปี ปัจจุบัน | F36: Positive | G36: Medium | L36: Not Start
A37: ="TC_Create_content_"&(ROW()-ROW($A$12)+1) -> TC_Create_content_26 | B37: ตรวจสอบ หน้า สคริปต์ กรณี กด ปุ่ม "คัดลอกสคริปต์" และ กำหนดวันโพสต์ "วันที่ย้อนหลัง / เดือนย้อนหลัง / ปี ปัจจุบัน" ระบบแสดงหน้าจอถูกต้อง เงื่อนไข - กดปุ่ม : คัดลอกสคริปต์ - กำหนดวันโพสต์ : "วันที่ย้อนหลัง / เดือนย้อนหลัง / ปี ปัจจุบัน" | F37: Positive | G37: Medium | L37: Not Start
A38: ="TC_Create_content_"&(ROW()-ROW($A$12)+1) -> TC_Create_content_27 | B38: ตรวจสอบ หน้า สคริปต์ กรณี กด ปุ่ม "คัดลอกบรีฟทั้งหมด" และ "ไม่กำหนดวันโพสต์" ระบบแสดงหน้าจอถูกต้อง เงื่อนไข - กดปุ่ม : คัดลอกสคริปต์ - กำหนดวันโพสต์ : ไม่กำหนดวันโพสต์ | F38: Positive | G38: Medium | L38: Not Start
A39: ="TC_Create_content_"&(ROW()-ROW($A$12)+1) -> TC_Create_content_28 | B39: ตรวจสอบ หน้า สคริปต์ กรณี กด ปุ่ม "คัดลอกบรีฟทั้งหมด" และ "ลบสคริปต์" ระบบแสดงหน้าจอถูกต้อง เงื่อนไข - กดปุ่ม : คัดลอกบรีฟทั้งหมด - กดปุ่ม : ลบสคริปต์ - popup : ลบ | F39: Negative | G39: Medium | L39: Not Start
A40: ="TC_Create_content_"&(ROW()-ROW($A$12)+1) -> TC_Create_content_29 | B40: ตรวจสอบ หน้า สคริปต์ กรณี กด ปุ่ม "คัดลอกบรีฟทั้งหมด" และ "ลบสคริปต์" ระบบแสดงหน้าจอถูกต้อง เงื่อนไข - กดปุ่ม : คัดลอกบรีฟทั้งหมด - กดปุ่ม : ลบสคริปต์ - popup : ยกเลิก | F40: Negative | G40: Medium | L40: Not Start
A41: ="TC_Create_content_"&(ROW()-ROW($A$12)+1) -> TC_Create_content_30 | B41: ตรวจสอบ หน้า สคริปต์ กรณี กด ปุ่ม "แก้ไข" Field : "Hook" และกด "บันทึกการแก้ไข" ระบบแสดงหน้าจอถูกต้อง เงื่อนไข - กดปุ่ม : แก้ไข - Field : "Hook" : แก้ไขสคริปต์เพิ่มเติม - กดปุ่ม : "บันทึกการแก้ไข" | F41: Positive | G41: Medium | L41: Not Start
A42: ="TC_Create_content_"&(ROW()-ROW($A$12)+1) -> TC_Create_content_31 | B42: ตรวจสอบเมนู : สร้างคอนเทนต์ เลือก Tab สร้างคลิป เลือก เป้าหมายคลิป "ปิดการขาย และความยาวคลิป 60 วิ" กรณี "ไม่เลือกแบบสคริปต์ที่ AI Gen มาให้" --> กดเมนู "บอร์ดคอนเทนต์" โดยมีรายละเอียดดังนี้ และ ระบบแสดงหน้าจอถูกต้อง เงื่อนไข - กดปุ่ม : สร้างคอนเทนต์ - หัวข้อคลิป : กรอกข้อมูล - มุมที่อยากเน้น : - - เป้าหมายคลิป : ปิดการขาย - สูตรสร้าง : ผลลัพธ์เคสจริง - ความยาว : 60 วิ - กดปุ่ม : Generate - สคริปต์ AI Gen : ไม่เลือก | D42: 1 | E42: -ระบบแสดงรายการ สคริปต์ ที่ AI Gen มาให้โดยมี คะแนน 10/10 ระบุความสมบรูณ์ของสคริป -หน้า บอร์ดคอนเทนต์ แสดงรายการสริปต์ ถูกต้อง | F42: Positive | G42: High | L42: Not Start
A43: ="TC_Create_content_"&(ROW()-ROW($A$12)+1) -> TC_Create_content_32 | B43: ตรวจสอบ หน้า บอร์ดคอนเทนต์ กรณี "ไม่เลือกแบบสคริปต์ที่ AI Gen มาให้" ระบบแสดงหน้าจอถูกต้อง เงื่อนไข - กดปุ่ม : บอร์ดคอนเทนต์ | E43: -หน้า บอร์ดคอนเทนต์ แสดงรายการสริปต์ ถูกต้อง -สคริปต์ที่ไม่ได้เลือก แบบสคริปต์ กล่องสคริปต์ ไม่แสดงรายละเอียดสคริป -แสดงปุ่ม "เลือกแบบก่อน" - แสดงวันที่ / เดือน / ปี ที่กดสร้างวคริปต์ | L43: Not Start
A44: ="TC_Create_content_"&(ROW()-ROW($A$12)+1) -> TC_Create_content_33 | B44: ตรวจสอบ หน้า บอร์ดคอนเทนต์ กรณี กดปุ่ม "เลือกแบบก่อน และเลือกแบบ A" ระบบแสดงหน้าจอถูกต้อง เงื่อนไข - กดปุ่ม : บอร์ดคอนเทนต์ - กด : กล่อง "คอนเทนต์" - กดปุ่ม : เลือกแบบก่อน - กดเลือกแบบ : A | E44: - ระบบแสดงไม่แสดง รายละอียดสคริปต์ - ระบบแสดง แบบ "สคริปต์" A/B/C พร้อมรายละเอียดสคริปต์ และปุ่ม "ใช้แบบนี้" - ระบบแสดงรายละเอียดสคริปต์ ทั้งหมด - ระบบแสดงปุ่ม : คัดลอกสคริปต์ / คัดลอกบรีฟทั้งหมด / แก้ไข - ระบบแสดง กำหนดวันโพสต์ - ระบบแสดง ปุ่ม "ลบสคริปต์" | F44: Positive | G44: Low | L44: Not Start
A45: ="TC_Create_content_"&(ROW()-ROW($A$12)+1) -> TC_Create_content_34 | B45: ตรวจสอบ หน้า บอร์ดคอนเทนต์ กรณี "มีการสร้างสคริปต์ = 1 สคริปต์" ระบบแสดงหน้าจอถูกต้อง เงื่อนไข - กดปุ่ม : บอร์ดคอนเทนต์ | E45: - ระบบแสดง หน้า บอร์ดคอนเทนต์ มีรายการ "กล่องคอนเทนต์" แสดงอยู่ 1 รายการ ถูกต้อง - กล่องคอนเทนต์ แสดง"รายละเอียด" สคริปต์ ที่ AI Gen ให้ จากแบบที่เลือก A/B/C จากที่ผู้ใช้งานเลือก - แสดงวันที่ / เดือน / ปี ที่กดสร้างวคริปต์ - แสดงปุ่ม คัดลอกสคริปต์ / คัดลอกบรีฟทั้งหมด | F45: Positive | G45: Low | L45: Not Start
A46: ="TC_Create_content_"&(ROW()-ROW($A$12)+1) -> TC_Create_content_35 | B46: ตรวจสอบ หน้า บอร์ดคอนเทนต์ กรณี "มีการสร้างสคริปต์ > 3 สคริปต์ และกดที่ "พื้นที่ว่าง" ในกล่องคอนเทนต์ " ระบบแสดงหน้าจอถูกต้อง เงื่อนไข - กดปุ่ม : บอร์ดคอนเทนต์ - กล่องคอนเทนต์ : กดพื้นที่ว่าง | E46: - ระบบแสดงรายละเอียดสคริปต์ ทั้งหมด - ระบบแสดงปุ่ม : คัดลอกสคริปต์ / คัดลอกบรีฟทั้งหมด / แก้ไข - ระบบแสดง กำหนดวันโพสต์ - ระบบแสดง ปุ่ม "ลบสคริปต์" | F46: Positive | G46: Low | L46: Not Start
...

Sheet Business_Profile
B1: =HYPERLINK("#Document!A1", "Refer to sheet Document") -> Refer to sheet Document
A3: Total TC. | B3: =COUNTIF(A11:A83,"TC_*") -> 13
A4: Test Cases ID | B4: Test Case Description | C4: Pre-Conditions | D4: Test Step | E4: Expected Result | F4: Positive/Negative | G4: Priority | H4: Test Data | I4: Tester | J4: Execution Plan | K4: Execution date | L4: Test Result | M4: Remark
A10: CreatorDee
A11: Scenario : Case validations ตั้งค่า "โปรไฟล์ธุรกิจ"
A12: ="TC_Business_Profile_"&(ROW()-ROW($A$12)+1) -> TC_Business_Profile_1 | B12: ตรวจสอบเมนู :โปรไฟล์ธุรกิจ กรณี "กรอกข้อมูลครบถ้วน"ระบบบันทึกข้อมูลและแสดงหน้าจอถูกต้อง | F12: Positive | G12: Medium | L12: Not Start
A13: ="TC_Business_Profile_"&(ROW()-ROW($A$12)+1) -> TC_Business_Profile_2 | B13: ตรวจสอบเมนู :โปรไฟล์ธุรกิจ กรณี Field : ชื่อ/นามปากกา "กรอกข้อมูลอักขระพิเศษ" และกรอกข้อมูล Field อื่นครบถ้วน แล้วกด "บันทึกโปร์ไฟล์" ระบบแสดง error ถูกต้อง | F13: Negative | G13: High | L13: Not Start
A14: ="TC_Business_Profile_"&(ROW()-ROW($A$12)+1) -> TC_Business_Profile_3 | B14: ตรวจสอบเมนู :โปรไฟล์ธุรกิจ กรณี Field : เลขบัตรประชาชน "กรอกตัวเลขเกิน 13 หลัก" และกรอกข้อมูล Field อื่นครบถ้วน แล้วกด "บันทึกโปร์ไฟล์" ระบบแสดง error ถูกต้อง | F14: Negative | G14: High | L14: Not Start
A15: ="TC_Business_Profile_"&(ROW()-ROW($A$12)+1) -> TC_Business_Profile_4 | B15: ตรวจสอบเมนู :โปรไฟล์ธุรกิจ กรณี Field : โทรศัพท์ "กรอกตัวเลขเกิน 10 หลัก" แล้วกด "บันทึกโปร์ไฟล์" ระบบแสดง error ถูกต้อง | F15: Negative | G15: Low | L15: Not Start
A16: ="TC_Business_Profile_"&(ROW()-ROW($A$12)+1) -> TC_Business_Profile_5 | B16: ตรวจสอบเมนู :โปรไฟล์ธุรกิจ กรณี Field : e-mail กรอกข้อมูล "ภาษาไทย/อักขระพิเศษ" แล้วกด "บันทึกโปร์ไฟล์" ระบบแสดง error ถูกต้อง | F16: Negative | G16: Low | L16: Not Start
A17: ="TC_Business_Profile_"&(ROW()-ROW($A$12)+1) -> TC_Business_Profile_6 | B17: ตรวจสอบเมนู :โปรไฟล์ธุรกิจ กรณี "อัปโหลดโลโก้ใหญ่เกิน" ระบบแสดง error ถูกต้อง | F17: Negative | G17: Low | L17: Not Start
A18: ="TC_Business_Profile_"&(ROW()-ROW($A$12)+1) -> TC_Business_Profile_7 | B18: ตรวจสอบเมนู :โปรไฟล์ธุรกิจ กรณี Field เลขบัญชี "กรอกเลขบัญชี เกิน 10 หลัก" ระบบแสดง error ถูกต้อง | F18: Negative | G18: Medium | L18: Not Start
A19: ="TC_Business_Profile_"&(ROW()-ROW($A$12)+1) -> TC_Business_Profile_8 | B19: ตรวจสอบเมนู :โปรไฟล์ธุรกิจ กรณี Field : ชื่อบัญชี "กรอกข้อมูลอักขระพิเศษ" และกรอกข้อมูล Field อื่นครบถ้วน แล้วกด "บันทึกโปร์ไฟล์" ระบบแสดง error ถูกต้อง | F19: Negative | G19: High | L19: Not Start
A20: ="TC_Business_Profile_"&(ROW()-ROW($A$12)+1) -> TC_Business_Profile_9 | B20: ตรวจสอบเมนู :โปรไฟล์ธุรกิจ กรณี Field : พร้อมเพย์ "กรอกตัวเลขเกิน 10 หลัก" ระบบแสดง error ถูกต้อง | F20: Negative | G20: Low | L20: Not Start
A21: ="TC_Business_Profile_"&(ROW()-ROW($A$12)+1) -> TC_Business_Profile_10 | B21: ตรวจสอบเมนู :โปรไฟล์ธุรกิจ กรณี แก้ไขข้อมูล ธนาคาร เลือก "-ไม่ระบุ-" กด "บันทึกโปร์ไฟล์" และไปทำการออกเอหสาร "ใบแจ้งหนี้" ระบบแสดงข้อมูลถูกต้อง | F21: Negative | G21: High | L21: Not Start
A22: ="TC_Business_Profile_"&(ROW()-ROW($A$12)+1) -> TC_Business_Profile_11 | B22: ตรวจสอบเมนู :โปรไฟล์ธุรกิจ กรณี "ไม่ ✔️ จดทะเบียน VAT " และไปออกเอกสาร "ใบเสนอราคา" ระบบแสดงข้อมูลถูกต้อง | F22: Negative | G22: High | L22: Not Start
A23: ="TC_Business_Profile_"&(ROW()-ROW($A$12)+1) -> TC_Business_Profile_12 | B23: ตรวจสอบเมนู :โปรไฟล์ธุรกิจ กรณี "✔️จดทะเบียน VAT " และไปออกเอกสาร "ใบเสนอราคา" ระบบแสดงข้อมูลถูกต้อง | F23: Negative | G23: High | L23: Not Start
A24: ="TC_Business_Profile_"&(ROW()-ROW($A$12)+1) -> TC_Business_Profile_13 | B24: ตรวจสอบเมนู :โปรไฟล์ธุรกิจ กรณี " หัก ณ ที่จ่าย default (%) = 3 " และไปออกเอกสาร "ใบเสนอราคา" ระบบแสดงข้อมูล หัก ณ ที่จ่าย default (%) ถูกต้อง | F24: Negative | G24: High | L24: Not Start
E44: Pass | F44: =COUNTIF(L12:L24,"Pass") -> 0 | G44: =(F44/F50)*100 -> 0 | H44: %
E45: Fail | F45: =COUNTIF(L12:L24,"Pass") -> 0 | G45: =(F45/F50)*100 -> 0 | H45: %
E46: Not Start | F46: =COUNTIF(L12:L24,"Not Start") -> 13 | G46: =(F46/F50)*100 -> 100 | H46: %
E47: Pending | F47: =COUNTIF(L12:L24,"Pending") -> 0 | G47: =(F47/F50)*100 -> 0 | H47: %
E48: Deferred | F48: =COUNTIF(#REF!,"Deferred") -> 0 | G48: =(F48/F50)*100 -> 0 | H48: %
E49: Not Applicable | F49: =COUNTIF(L12:L24,"Not Applicable") -> 0 | G49: =(F49/F50)*100 -> 0 | H49: %
E50: Total | F50: =SUM(F44:F49) -> 13 | G50: =SUM(G44:G49) -> 100 | H50: %
E51: Summary Execute Rate | G51: =G44+G45+G47+G49 -> 0
E52: Summary Pass Rate | G52: =F44/(F50-F49-F47) -> 0

Sheet User_Package
B1: =HYPERLINK("#Document!A1", "Refer to sheet Document") -> Refer to sheet Document
A3: Total TC. | B3: =COUNTIF(A12:A78,"TC_*") -> 62
A4: Test Cases ID | B4: Test Case Description | C4: Pre-Conditions | D4: Test Step | E4: Expected Result | F4: Positive/Negative | G4: Priority | H4: Test Data | I4: Tester | J4: Execution Package | K4: Execution date | L4: Test Result | M4: Remark
A10: Scenario : Case validations : เมนู "แพ็กเกจสมาชิก"
A11: ="TC_User_Package_"&(ROW()-ROW($A$11)+1) -> TC_User_Package_1 | B11: ตรวจสอบเมนู : แพ็กเกจสมาชิก กรณี : User สมัครใช้งานครั้งแรก - New User | E11: 1. ระบบต้อง default ที่ Free Package 2. แสดงปุ่มทดลองใช้งานฟรี 14 วันที่ตัว Pro Package | F11: Positive | G11: High | I11: James | K11: 46237 | L11: PASS
A12: ="TC_User_Package_"&(ROW()-ROW($A$11)+1) -> TC_User_Package_2 | B12: ตรวจสอบเมนู : แพ็กเกจสมาชิก กรณี : User เคยใช้ตัว Pro แต่ยกเลิกการ subscription ไปแล้ว - Old User | E12: 1. ระบบต้อง default ที่ Free Package 2. ไม่แสดงปุ่มทดลองใช้งานฟรี 14 วันที่ตัว Pro Package | F12: Positive | G12: High | I12: James | K12: 46237 | L12: PASS
A13: ="TC_User_Package_"&(ROW()-ROW($A$11)+1) -> TC_User_Package_3 | B13: ตรวจสอบเมนู : แพ็กเกจสมาชิก กรณี : User สมัครใช้งานครั้งแรก และ ทำการทดลองใช้ตัว Pro Package 14 วัน - New User - Activate Free Trial | C13: Pre-Conditions | E13: 1. ระบบต้อง default ที่ Pro Package 2. แสดงวันที่ต่ออายุอัตโนมัติ (14 วันหลังจากจากรับสิทธิ์ ทดลองใช้งาน) 3. แสดงปุ่ม "จัดการการเรียกเก็บเงิน" | F13: Positive | G13: High | I13: James | K13: 46238 | L13: PASS | M13: https://trello.com/c/9qRGckij
A14: ="TC_User_Package_"&(ROW()-ROW($A$11)+1) -> TC_User_Package_4 | B14: ตรวจสอบเมนู : แพ็กเกจสมาชิก กรณี : User สมัครใช้งานครั้งแรก และ ซื้อ Pro Package เลยแบบรายเดือน (ข้ามทดลองใช้งาน) - ไม่เคยใช้ Free Trial - ซื้อรายเดือน | C14: Pre-Conditions | E14: 1. ระบบต้อง default ที่ Pro Package 2. แสดงวันที่ต่ออายุอัตโนมัติ (44 วันหลังจากสมัคร -> Pro Package (30 days) + Free trial (14 days) 2. แสดงวันที่ต่ออายุอัตโนมัติ 30 วันหลังจากสมัคร -> Pro Package (30 days) 3. แสดงปุ่ม "จัดการการเรียกเก็บเงิน" | F14: Positive | G14: High | I14: James | K14: 46237 | L14: PASS
A15: ="TC_User_Package_"&(ROW()-ROW($A$11)+1) -> TC_User_Package_5 | B15: ตรวจสอบเมนู : แพ็กเกจสมาชิก กรณี : User สมัครใช้งานครั้งแรก และ ซื้อ Pro Package เลยแบบรายปี (ข้ามทดลองใช้งาน) - ไม่เคยใช้ Free Trial - ซื้อรายปี | C15: Pre-Conditions | E15: 1. ระบบต้อง default ที่ Pro Package 2. แสดงวันที่ต่ออายุอัตโนมัติ (379 วันหลังจากสมัคร -> Pro Package (365 days) + Free trial (14 days) 2. แสดงวันที่ต่ออายุอัตโนมัติ 365 วันหลังจากสมัคร -> Pro Package (365 days) 3. ราคาต้องถูกลง 2 เดือน 4. แสดงปุ่ม "จัดการการเรียกเก็บเงิน" | F15: Positive | G15: High | I15: James | K15: 46237 | L15: PASS
A16: ="TC_User_Package_"&(ROW()-ROW($A$11)+1) -> TC_User_Package_6 | B16: ตรวจสอบเมนู : แพ็กเกจสมาชิก กรณี : User กำลังอยู่ในช่วงทดลองใช้งาน Pro และตัดสินใจสมัคร Package Pro - Free Trial Activating - ซื้อแพ็กเกจ Pro | C16: Pre-Conditions | E16: 1. ระบบต้อง default ที่ Pro Package 2. แสดงวันที่ต่ออายุอัตโนมัติ (วันที่คงเหลือของ Free Trail + วันที่ของ package ที่ซื้อ (Monthly/Weekly)) 2. ระบบต้อง Reset วันที่คงเหลือตาม package ที่ซื้อ (โดยไม่เอาวันที่คงเหลือของ Free trial มาบวก) 3. แสดงปุ่ม "จัดการการเรียกเก็บเงิน" | F16: Positive | G16: High | I16: James | K16: 46238 | L16: PASS
A17: ="TC_User_Package_"&(ROW()-ROW($A$11)+1) -> TC_User_Package_7 | B17: ตรวจสอบเมนู : แพ็กเกจสมาชิก กรณี : User ใช้แพ็กเกจแบบรายเดือนอยู่ และ ปล่อยให้ระบบต่ออายุอัตโนมัติ แบบมีวงเงินในบัตรเครดิตเพียงพอ - รายเดือน - ต่ออายุอัตโนมัติ | C17: Pre-Conditions | E17: 1. ระบบสามารถต่ออายุได้ 2. แสดงวันที่ต่ออายุอัตโนมัติ (30 วันหลังจากวันที่ต่ออายุ) 3. แสดงปุ่ม "จัดการการเรียกเก็บเงิน" | F17: Positive | G17: High | I17: James | K17: 46238 | L17: FAIL | M17: https://trello.com/c/mJi7vaRw
